Workbook

Sheet PROFIL PENELITI
A2: PROFIL PENELITI
A5: 1 | B5: Nama Peneliti | D5: : | E5: Atikah Nurfadia
A6: 2 | B6: Jenis Lembaga | D6: : | E6: Pendidikan Tinggi
A7: 3 | B7: Nama Lembaga | D7: : | E7: Politeknik Statistika STIS | L7: PERGURUAN TINGGI | W7: Semua Bidang | AA7: Baru
A8: 4 | B8: Jabatan Pengusul | D8: : | E8: Mahasiswa | L8: KOPERTIS | W8: Energi | AA8: Berlanjut
A9: 5 | B9: NIM | D9: : | E9: 222212522 | L9: LEMBAGA LPNK | W9: Transportasi | AA9: Selesai
A10: 6 | B10: NIDN (Jika Dosen) | D10: : | L10: LITBANG KEMENTERIAN | W10: TIK
A11: 7 | B11: Alamat | D11: : | L11: LITBANG DAERAH | W11: Pangan
A12: 8 | B12: Kota | D12: : | L12: LITBANG PERUSAHAAN | W12: Kesehatan & Obat
A13: 9 | B13: Telepon | D13: : | W13: Material Maju
A14: 10 | B14: Email | D14: : | W14: Maritim
A19: DATA TEKNOLOGI YANG DIKEMBANGKAN
A21: Identitas Umum
A22: 1 | B22: Nama Kegiatan Penelitian | D22: : | E22: Penyusunan Model Simulasi Spatial Spillover Effects Sektor Pariwisata Menggunakan Interregional Input-Output Network dan Gospatial Big Data
A23: 2 | B23: Nama Teknologi yang Dikembangkan | D23: : | E23: Web Story Dashboard Simulasi Spillover Pariwisata Bali
A24: 3 | B24: Bidang Teknologi | D24: : | E24: TIK
A25: 4 | B25: Deskripsi Teknologi | D25: : | E25: Web story interaktif berbasis HTML/JS untuk memvisualisasikan hasil simulasi IRIO spillover pariwisata Bali
A26: 5 | B26: Status Riset | D26: : | E26: Selesai
A27: 6 | B27: Publikasi | D27: : | E27: Skripsi
A28: Pendanaan
A29: 7 | B29: Sumber Dana | D29: : | E29: Mandiri
A30: 8 | B30: Skema Pembiayaan | D30: :
A31: 9 | B31: Besaran Dana | D31: :
A32: Koordinator Penelitian
A33: 10 | B33: Nama | D33: : | E33: Dr. Eng. Arie Wahyu Wijayanto, SST., MT.
A34: 11 | B34: Telepon | D34: : | E34: 085890363680
A35: 12 | B35: Email | D35: : | E35: ariewahyu@stis.ac.id
A36: 13 | B36: Alamat | D36: :
A37: 14 | B37: Lembaga | D37: : | E37: Politeknik Statistika STIS

Sheet IDENTITAS UMUM
A2: DATA TEKNOLOGI YANG DIKEMBANGKAN
A4: Identitas Umum
A5: 1 | B5: Nama Kegiatan Penelitian | D5: : | E5: Penyusunan Model Simulasi Spatial Spillover Effects Sektor Pariwisata Menggunakan Interregional Input-Output Network dan Gospatial Big Data
A6: 2 | B6: Nama Teknologi yang Dikembangkan | D6: : | E6: Web Story Dashboard Simulasi Spillover Pariwisata Bali
A7: 3 | B7: Bidang Teknologi | D7: : | E7: TIK | W7: Semua Bidang | AA7: Baru
A8: 4 | B8: Deskripsi Teknologi | D8: : | E8: Web story interaktif berbasis HTML/JS untuk memvisualisasikan hasil simulasi IRIO spillover pariwisata Bali | W8: Energi | AA8: Berlanjut
A9: 5 | B9: Status Riset | D9: : | E9: Selesai | W9: Transportasi | AA9: Selesai
A10: 6 | B10: Publikasi | D10: : | E10: Skripsi | W10: TIK
A11: Pendanaan | W11: Hankam
A12: 7 | B12: Sumber Dana | D12: : | E12: Mandiri | W12: Pangan
A13: 8 | B13: Skema Pembiayaan | D13: : | W13: Kesehatan & Obat
A14: 9 | B14: Besaran Dana | D14: : | W14: Material Maju
A15: Koordinator Penelitian | W15: Sosial Humaniora
A16: 10 | B16: Nama | D16: : | E16: Dr. Eng. Arie Wahyu Wijayanto, SST., MT. | W16: Maritim
A17: 11 | B17: Telepon | D17: : | E17: 085890363680 | W17: Kebencanaan dan Lingkungan
A18: 12 | B18: Email | D18: : | E18: ariewahyu@stis.ac.id | W18: Lainnya
A19: 13 | B19: Alamat | D19: :
A20: 14 | B20: Lembaga | D20: : | E20: Politeknik Statistika STIS

Sheet PENGUKURAN TKT SOFTWARE
A3: INDIKATOR TKT BIDANG SOFTWARE
B5: TKT 1 | C5: No | D5: Indikator | E5: Pengukuran | G5: Keterangan | H5: NILAI TKT | O5: 0
C6: 1 | D6: Merupakan tingkat terendah dari kesiapan teknologi perangkat lunak | E6: 1 | G6: {=LOOKUP(E9,{0,0.79},{"PENGUKURAN BERHENTI DI SINI","PENGUKURAN DILANJUTKAN KE TKT BERIKUTNYA"})} -> PENGUKURAN DILANJUTKAN KE TKT BERIKUTNYA | H6: {=LOOKUP(E9,{0,0.79},{"0","LANJUT"})} -> LANJUT | O6: 0.2
C7: 2 | D7: Merupakan ranah baru dalam perangkat lunak yang sedang didalami oleh komunitas riset dasar | E7: 1 | O7: 0.4
C8: 3 | D8: Mencakup juga pengembangan dari penggunaan tingkat dasar, sifat dasar dari arsitektur perangkat lunak, formulasi matematika, dan algoritma umum | E8: 1 | O8: 0.6
C9: Nilai Rata-rata | E9: =SUM(E6:E8)/3 -> 1 | O9: 0.8
O10: 1
B11: TKT 2 | C11: No | D11: Indikator | E11: Pengukuran | G11: Keterangan | H11: NILAI TKT
C12: 1 | D12: Setelah prinsip dasar teramati, berlanjut pada pembuatan aplikasi yang bersifat praktis | E12: 1 | G12: {=LOOKUP(E15,{0,0.79},{"PENGUKURAN BERHENTI DI SINI","PENGUKURAN DILANJUTKAN KE TKT BERIKUTNYA"})} -> PENGUKURAN DILANJUTKAN KE TKT BERIKUTNYA | H12: {=LOOKUP(E15,{0,0.79},{"1","LANJUT"})} -> LANJUT
C13: 2 | D13: Aplikasi bersifat spekulatif, dan terdapat kemungkinan tidak memiliki bukti atau analisis rinci untuk mendukung asumsi yang ada/dilakukan | E13: 1
C14: 3 | D14: Contoh-contoh dibatasi pada studi analitik dengan menggunakan data sintetis (buatan) | E14: 1
C15: Nilai Rata-rata | E15: =SUM(E12:E14)/3 -> 1
B17: TKT 3 | C17: No | D17: Indikator | E17: Pengukuran | G17: Keterangan | H17: NILAI TKT
C18: 1 | D18: Terdapat inisiasi proses penelitian dan pengembangan yang dilakukan secara aktif | E18: 1 | G18: {=LOOKUP(E21,{0,0.79},{"PENGUKURAN BERHENTI DI SINI","PENGUKURAN DILANJUTKAN KE TKT BERIKUTNYA"})} -> PENGUKURAN DILANJUTKAN KE TKT BERIKUTNYA | H18: {=LOOKUP(E21,{0,0.79},{"2","LANJUT"})} -> LANJUT
C19: 2 | D19: Kelayakan ilmiah ditunjukkan melalui studi analitik dan laboratorium | E19: 1
C20: 3 | D20: Mencakup juga pengembangan dari lingkungan fungsi terbatas untuk memvalidasi sifat kritis dan prediksi analitis menggunakan : (1) komponen perangkat lunak yang tidak terintegrasi dan (2) sebagian data yang mewakili | E20: 1
C21: Nilai Rata-rata | E21: =SUM(E18:E20)/3 -> 1
B23: TKT 4 | C23: No | D23: Indikator | E23: Pengukuran | G23: Keterangan | H23: NILAI TKT
C24: 1 | D24: Komponen dasar dari perangkat lunak dasar terintegrasi bekerja secara bersama-sama | E24: 1 | G24: {=LOOKUP(E29,{0,0.79},{"PENGUKURAN BERHENTI DI SINI","PENGUKURAN DILANJUTKAN KE TKT BERIKUTNYA"})} -> PENGUKURAN DILANJUTKAN KE TKT BERIKUTNYA | H24: {=LOOKUP(E29,{0,0.79},{"3","LANJUT"})} -> LANJUT
C25: 2 | D25: Relatif primitif bila sisi efisiensi dan kehandalan (robustness) dibandingkan dengan sistem/produk akhirnya | E25: 1
C26: 3 | D26: Pengembangan arsitektur dimulai dengan cakupan isu-isu terkait interoperabilitas, kehandalan, kemudahan pemeliharaan, kemampuan peningkatan, skalabilitas, dan keamanan | E26: 1
C27: 4 | D27: Terdapat usaha penyesuaian dengan elemen (teknologi) terkini | E27: 1
C28: 5 | D28: Prototipe yang ada dikembangkan untuk menunjukkan aspek yang berbeda pada sistem/produk akhirnya | E28: 1
C29: Nilai Rata-rata | E29: =SUM(E24:E28)/5 -> 1
B31: TKT 5 | C31: No | D31: Indikator | E31: Pengukuran | G31: Keterangan | H31: NILAI TKT
C32: 1 | D32: Merupakan tingkatan dimana teknologi perangkat lunak yang dikembangkan siap untuk diintegrasikan dengan sistem eksisting | E32: 1 | G32: {=LOOKUP(E38,{0,0.79},{"PENGUKURAN BERHENTI DI SINI","PENGUKURAN DILANJUTKAN KE TKT BERIKUTNYA"})} -> PENGUKURAN DILANJUTKAN KE TKT BERIKUTNYA | H32: {=LOOKUP(E38,{0,0.79},{"4","LANJUT"})} -> LANJUT
C33: 2 | D33: Implementasi prototipe yang sesuai/patuh dengan lingkungan/antarmuka dari target | E33: 1
C34: 3 | D34: Dilakukan eksperimen terhadap permasalahan yang sesungguhnya (real) | E34: 1
C35: 4 | D35: Melakukan simulasi terhadap antarmuka dari sistem eksisting | E35: 1
C36: 5 | D36: Arsitektur perangkat lunak sistem selesai | E36: 1
C37: 6 | D37: Algoritma berjalan pada (multi) prosesor di lingkungan operasional dengan karakteristik yang sesuai ekspektasi | E37: 1
C38: Nilai Rata-rata | E38: =SUM(E32:E37)/6 -> 1
B40: TKT 6 | C40: No | D40: Indikator | E40: Pengukuran | G40: Keterangan | H40: NILAI TKT
C41: 1 | D41: Merupakan tingkatan dimana kelayakan rekayasa dari teknologi perangkat lunak ditunjukkan | E41: 0 | G41: {=LOOKUP(E43,{0,0.79},{"PENGUKURAN BERHENTI DI SINI","PENGUKURAN DILANJUTKAN KE TKT BERIKUTNYA"})} -> PENGUKURAN BERHENTI DI SINI | H41: {=LOOKUP(E43,{0,0.79},{"5","LANJUT"})} -> 5
C42: 2 | D42: Mencakup juga implementasi prototipe laboratorium dengan permasalahan realistik skala penuh, dimana teknologi perangkat lunak terintegrasi secara parsial dengan perangkat keras/lunak dari sistem eksisting | E42: 0
C43: Nilai Rata-rata | E43: =SUM(E41:E42)/2 -> 0
B45: TKT 7 | C45: No | D45: Indikator | E45: Pengukuran | G45: Keterangan | H45: NILAI TKT
C46: 1 | D46: Merupakan tingkatan dimana kelayakan program dari teknologi perangkat lunak ditunjukkan | E46: 0 | G46: {=LOOKUP(E48,{0,0.79},{"PENGUKURAN BERHENTI DI SINI","PENGUKURAN DILANJUTKAN KE TKT BERIKUTNYA"})} -> PENGUKURAN BERHENTI DI SINI | H46: {=LOOKUP(E48,{0,0.79},{"6","LANJUT"})} -> 6
C47: 2 | D47: Mencakup juga implementasi prototipe lingkungan operasional, dimana fungsi risiko teknis yang bersifat kritikal tersedia untuk ditunjukkan dan diuji dalam kondisi teknologi perangkat lunak tersebut terintegrasi secara baik dengan perangkat keras/lunak dari sistem operasional | E47: 0
C48: Nilai Rata-rata | E48: =SUM(E46:E47)/2 -> 0
...

Sheet RINGKASAN
H3: KEMENTERIAN RISET, TEKNOLOGI DAN PENDIDIKAN TINGGI
H4: DIREKTORAT JENDERAL PENGUATAN RISET DAN PENGEMBANGAN
H5: Jl. M. H. Thamrin No. 8 Jakarta Pusat 10340-Gedung II BPPT Lantai 19
H6: Telepon 021 3169758 Faksimile 021 3102156/31023902
H7: Homepage : www.ristekdikti.go.id
G9: RINGKASAN HASIL
G10: PENGUKURAN TINGKAT KESIAPTERAPAN TEKNOLOGI (TKT)
R12: No:
G13: Nama/Judul Teknologi | K13: ='IDENTITAS UMUM'!E6 -> Web Story Dashboard Simulasi Spillover Pariwisata Bali
G14: Bidang Teknologi | K14: ='IDENTITAS UMUM'!E7 -> TIK
G15: Pimpinan Program / Kegiatan | K15: ='IDENTITAS UMUM'!E16 -> Dr. Eng. Arie Wahyu Wijayanto, SST., MT.
G16: Lembaga / Unit Pelaksana | K16: ='IDENTITAS UMUM'!E20 -> Politeknik Statistika STIS
G17: Alamat / Kontak | K17: ='IDENTITAS UMUM'!E19 -> 0
G18: Telp/Fax | K18: ='IDENTITAS UMUM'!E17 -> 085890363680
G19: Email | K19: ='IDENTITAS UMUM'!E18 -> ariewahyu@stis.ac.id
G21: Tanggal Pengukuran TKT | K21: :
G23: Level TKT yang dicapai : | K23: =P40 -> 5 | M23: (dari 9 level) | Q23: % Komplit Indikator = | T23: ='[1]TKT Farmasi'!Q11 -> 0
K27: TKT-Meter
N30: 9 | R30: 9
N31: 8 | R31: 8
N32: 7 | R32: 7
N33: 6 | R33: 6
N34: 5 | R34: 5
N35: 4 | R35: 4
N36: 3 | R36: 3
N37: 2 | R37: 2
N38: 1 | R38: 1
K40: TKT | O40: = | P40: =+MAX(C46:C54) -> 5
B46: =IF(OR(C46>0,D46>80%,),C46,0) -> 0 | C46: =IF(AND($C$58<=D46,D46<=100%,D47>=$C$58,D48>=$C$58),E46,0) -> 0 | D46: ='PENGUKURAN TKT SOFTWARE'!E63 -> 0 | E46: 9
B47: =IF(OR(C47>0,D47>80%,),C47,0) -> 0 | C47: =IF(AND($C$58<=D47,D47<=100%,D48>=$C$58,D49>=$C$58),E47,0) -> 0 | D47: ='PENGUKURAN TKT SOFTWARE'!E54 -> 0 | E47: 8
B48: =IF(OR(C48>0,D48>80%,),C48,0) -> 0 | C48: =IF(AND($C$58<=D48,D48<=100%,D49>=$C$58,D50>=$C$58),E48,0) -> 0 | D48: ='PENGUKURAN TKT SOFTWARE'!E48 -> 0 | E48: 7
B49: =IF(OR(C49>0,D49>80%,),C49,0) -> 0 | C49: =IF(AND($C$58<=D49,D49<=100%,D50>=$C$58,D51>=$C$58),E49,0) -> 0 | D49: ='PENGUKURAN TKT SOFTWARE'!E43 -> 0 | E49: 6
B50: =IF(OR(C50>0,D50>80%,),C50,0) -> 5 | C50: =IF(AND($C$58<=D50,D50<=100%,D51>=$C$58,D52>=$C$58),E50,0) -> 5 | D50: ='PENGUKURAN TKT SOFTWARE'!E38 -> 1 | E50: 5
B51: =IF(OR(C51>0,D51>80%,),C51,0) -> 4 | C51: =IF(AND($C$58<=D51,D51<=100%,D52>=$C$58,D53>=$C$58),E51,0) -> 4 | D51: ='PENGUKURAN TKT SOFTWARE'!E29 -> 1 | E51: 4
B52: =IF(OR(C52>0,D52>80%,),C52,0) -> 3 | C52: =IF(AND($C$58<=D52,D52<= 100%),E52, 0) -> 3 | D52: ='PENGUKURAN TKT SOFTWARE'!E21 -> 1 | E52: 3
B53: =IF(OR(C53>0,D53>80%,),C53,0) -> 2 | C53: =IF(AND($C$58<=D53,D53<= 100%,$C$54>=$C$58),E53, 0) -> 2 | D53: ='PENGUKURAN TKT SOFTWARE'!E15 -> 1 | E53: 2
B54: =IF(OR(C54>0,D54>80%,),C54,0) -> 1 | C54: =IF(AND($C$58<=D54,D54<=100%),E54,0) -> 1 | D54: ='PENGUKURAN TKT SOFTWARE'!E9 -> 1 | E54: 1
A56: % Set Point | C56: 0.8
A57: (default) | C57: 1
C58: =IF(C56=0,1,C56) -> 0.8
...
