Workbook

Sheet Petunjuk
A1: Matriks Pembobot Spasial Udara 34x34 — berbasis waktu tempuh dan jumlah transit
A3: CARA PAKAI (3 langkah)
A4: 1. Buka sheet Input_Konektivitas. Seluruh 561 pasangan provinsi sudah tercetak; kamu tinggal mengisi dua kolom kuning:
A5: Jumlah_Transit : 0 bila ADA penerbangan langsung, 1 bila sekali transit, 2 bila dua kali transit, dst.
A6: Waktu_Tempuh_jam : total waktu perjalanan dalam jam desimal (2 jam 15 menit = 2,25). Untuk rute langsung isi waktu terbangnya; untuk rute transit isi waktu total termasuk menunggu.
A7: Pasangan yang dibiarkan kosong dianggap tidak terhubung (bobot 0).
A8: 2. Atur dua eksponen di sheet Matrix_Bobot (sel B1 dan B2) bila perlu. Default: alpha = 1, beta = 0.
A9: 3. Matriks final ada di sheet W_Final (baku baris). Ini yang dipakai di analisis; tidak ada langkah lain.
A11: RUMUS BOBOT
A12: w_ij = 1 / ( T_ij ^ alpha x (1 + transit_ij) ^ beta ) lalu W*_ij = w_ij / jumlah baris ke-i
A13: alpha = 1, beta = 0 -> bobot murni 1/waktu tempuh (transit sudah ikut terhitung lewat waktu tunggu). DEFAULT.
A14: beta = 1 -> transit dihukum tambahan: langsung x1, 1x transit x1/2, 2x transit x1/3.
... A24: Ringkasan : pengecekan kelengkapan data.

Sheet Daftar_Provinsi
A1: No | B1: Provinsi | C1: Bandara acuan
A2: 1 | B2: Aceh | C2: BTJ
A3: 2 | B3: Sumatera Utara | C3: KNO
A4: 3 | B4: Sumatera Barat | C4: PDG
A5: 4 | B5: Riau | C5: PKU
A6: 5 | B6: Jambi | C6: DJB
A7: 6 | B7: Sumatera Selatan | C7: PLM
A8: 7 | B8: Bengkulu | C8: BKS
A9: 8 | B9: Lampung | C9: TKG
A10: 9 | B10: Kep. Bangka Belitung | C10: PGK
A11: 10 | B11: Kepulauan Riau | C11: BTH
A12: 11 | B12: DKI Jakarta | C12: CGK/HLP
A13: 12 | B13: Jawa Barat | C13: KJT/BDO
... A35: 34 | B35: Papua | C35: DJJ

Sheet Input_Konektivitas
A1: Jumlah_Transit dan Waktu_Tempuh_jam. Pasangan kosong = tidak terhubung.
A2: Provinsi_A | B2: Provinsi_B | C2: Jumlah_Transit | D2: Waktu_Tempuh_jam | E2: Sumber | F2: Catatan
A3: Aceh | B3: Sumatera Utara | C3: 0 | D3: 1.583 | E3: Traveloka
A4: Aceh | B4: Sumatera Barat | C4: 1 | D4: 6.5 | E4: Traveloka
A5: Aceh | B5: Riau | C5: 1 | D5: 3.5 | E5: Traveloka
A6: Aceh | B6: Jambi | C6: 1 | D6: 6.5 | E6: Traveloka
A7: Aceh | B7: Sumatera Selatan | C7: 1 | D7: 4.8333 | E7: Traveloka
A8: Aceh | B8: Bengkulu | C8: 1 | D8: 6.92 | E8: Traveloka
A9: Aceh | B9: Lampung | C9: 1 | D9: 5.58 | E9: Traveloka
A10: Aceh | B10: Kep. Bangka Belitung | C10: 1 | D10: 9.4167 | E10: Traveloka
A11: Aceh | B11: Kepulauan Riau | C11: 3 | D11: 24 | E11: Traveloka
A12: Aceh | B12: DKI Jakarta | C12: 0 | D12: 2.91777 | E12: Traveloka
A13: Aceh | B13: Jawa Barat | C13: 2 | D13: 20.75 | E13: Traveloka
A14: Aceh | B14: Jawa Tengah | C14: 1 | D14: 5.08333 | E14: Traveloka
... A16: Aceh | B16: Jawa Timur | C16: 1 | D16: 5.9167 | E16: Traveloka
A17: Aceh | B17: Banten
A18: Aceh | B18: Bali | C18: 1 | D18: 6.08333 | E18: Traveloka
A19: Aceh | B19: Nusa Tenggara Barat | C19: 1 | D19: 7.75 | E19: Traveloka
A20: Aceh | B20: Nusa Tenggara Timur | C20: 1 | D20: 12.25 | E20: Traveloka
A21: Aceh | B21: Kalimantan Barat | C21: 1 | D21: 5.5 | E21: Traveloka
A22: Aceh | B22: Kalimantan Tengah | C22: 1 | D22: 5.6667 | E22: Traveloka
A23: Aceh | B23: Kalimantan Selatan | C23: 1 | D23: 7.25 | E23: Traveloka
A24: Aceh | B24: Kalimantan Timur | C24: 1 | D24: 8.916677 | E24: Traveloka
A25: Aceh | B25: Kalimantan Utara | C25: 3 | D25: 21.75 | E25: Traveloka
A26: Aceh | B26: Sulawesi Utara | C26: 2 | D26: 19.8333 | E26: Traveloka
A27: Aceh | B27: Sulawesi Tengah | C27: 1 | D27: 13.5 | E27: Traveloka
A28: Aceh | B28: Sulawesi Selatan | C28: 1 | D28: 6.92 | E28: Traveloka
A29: Aceh | B29: Sulawesi Tenggara | C29: 1 | D29: 8.67 | E29: Traveloka
... A48: Sumatera Utara | B48: Jawa Timur | C48: 0 | D48: 3.17 | E48: Traveloka
A49: Sumatera Utara | B49: Banten
A50: Sumatera Utara | B50: Bali | C50: 1 | D50: 5.17 | E50: Traveloka
A51: Sumatera Utara | B51: Nusa Tenggara Barat | C51: 1 | D51: 5.5 | E51: Traveloka
A52: Sumatera Utara | B52: Nusa Tenggara Timur | C52: 1 | D52: 10.17 | E52: Traveloka
A53: Sumatera Utara | B53: Kalimantan Barat | C53: 1 | D53: 4.33 | E53: Traveloka
A54: Sumatera Utara | B54: Kalimantan Tengah | C54: 1 | D54: 5.25 | E54: Traveloka
A55: Sumatera Utara | B55: Kalimantan Selatan | C55: 1 | D55: 6.33 | E55: Traveloka
A56: Sumatera Utara | B56: Kalimantan Timur | C56: 1 | D56: 6.67 | E56: Traveloka
A57: Sumatera Utara | B57: Kalimantan Utara | C57: 1 | D57: 7.42 | E57: Traveloka
A58: Sumatera Utara | B58: Sulawesi Utara | C58: 1 | D58: 8.33 | E58: Traveloka
A59: Sumatera Utara | B59: Sulawesi Tengah | C59: 1 | D59: 9.33 | E59: Traveloka
...

Sheet Matrix_Waktu
A1: Waktu Tempuh Udara T_ij (jam)
A2: Otomatis dari Input_Konektivitas (simetris). Sel kosong = pasangan belum terisi / tidak terhubung.
A3: Asal \ Tujuan | B3: Aceh | C3: Sumatera Utara | D3: Sumatera Barat | E3: Riau | F3: Jambi | G3: Sumatera Selatan | H3: Bengkulu | I3: Lampung | J3: Kep. Bangka Belitung | K3: Kepulauan Riau | L3: DKI Jakarta | M3: Jawa Barat | N3: Jawa Tengah | O3: DI Yogyakarta | P3: Jawa Timur | Q3: Banten | R3: Bali | S3: Nusa Tenggara Barat | T3: Nusa Tenggara Timur | U3: Kalimantan Barat | V3: Kalimantan Tengah | W3: Kalimantan Selatan | X3: Kalimantan Timur | Y3: Kalimantan Utara | Z3: Sulawesi Utara | AA3: Sulawesi Tengah | AB3: Sulawesi Selatan | AC3: Sulawesi Tenggara | AD3: Gorontalo | AE3: Sulawesi Barat | AF3: Maluku | AG3: Maluku Utara | AH3: Papua Barat | AI3: Papua
A4: Aceh | B4: 0 | C4: =IF((COUNTIFS(Input_Konektivitas!$A$3:$A$563,$A4,Input_Konektivitas!$B$3:$B$563,C$3,Input_Konektivitas!$D$3:$D$563,">0")+COUNTIFS(Input_Konektivitas!$A$3:$A$563,C$3,Input_Konektivitas!$B$3:$B$563,$A4,Input_Konektivitas!$D$3:$D$563,">0"))=0,"",SUMIFS(Input_Konektivitas!$D$3:$D$563,Input_Konektivitas!$A$3:$A$563,$A4,Input_Konektivitas!$B$3:$B$563,C$3)+SUMIFS(Input_Konektivitas!$D$3:$D$563,Input_Konektivitas!$A$3:$A$563,C$3,Input_Konektivitas!$B$3:$B$563,$A4)) -> 1.583 | D4: =IF((COUNTIFS(Input_Konektivitas!$A$3:$A$563,$A4,Input_Konektivitas!$B$3:$B$563,D$3,Input_Konektivitas!$D$3:$D$563,">0")+COUNTIFS(Input_Konektivitas!$A$3:$A$563,D$3,Input_Konektivitas!$B$3:$B$563,$A4,Input_Konektivitas!$D$3:$D$563,">0"))=0,"",SUMIFS(Input_Konektivitas!$D$3:$D$563,Input_Konektivitas!$A$3:$A$563,$A4,Input_Konektivitas!$B$3:$B$563,D$3)+SUMIFS(Input_Konektivitas!$D$3:$D$563,Input_Konektivitas!$A$3:$A$563,D$3,Input_Konektivitas!$B$3:$B$563,$A4)) -> 6.5 | E4: =IF((COUNTIFS(Input_Konektivitas!$A$3:$A$563,$A4,Input_Konektivitas!$B$3:$B$563,E$3,Input_Konektivitas!$D$3:$D$563,">0")+COUNTIFS(Input_Konektivitas!$A$3:$A$563,E$3,Input_Konektivitas!$B$3:$B$563,$A4,Input_Konektivitas!$D$3:$D$563,">0"))=0,"",SUMIFS(Input_Konektivitas!$D$3:$D$563,Input_Konektivitas!$A$3:$A$563,$A4,Input_Konektivitas!$B$3:$B$563,E$3)+SUMIFS(Input_Konektivitas!$D$3:$D$563,Input_Konektivitas!$A$3:$A$563,E$3,Input_Konektivitas!$B$3:$B$563,$A4)) -> 3.5 | F4: =IF((COUNTIFS(Input_Konektivitas!$A$3:$A$563,$A4,Input_Konektivitas!$B$3:$B$563,F$3,Input_Konektivitas!$D$3:$D$563,">0")+COUNTIFS(Input_Konektivitas!$A$3:$A$563,F$3,Input_Konektivitas!$B$3:$B$563,$A4,Input_Konektivitas!$D$3:$D$563,">0"))=0,"",SUMIFS(Input_Konektivitas!$D$3:$D$563,Input_Konektivitas!$A$3:$A$563,$A4,Input_Konektivitas!$B$3:$B$563,F$3)+SUMIFS(Input_Konektivitas!$D$3:$D$563,Input_Konektivitas!$A$3:$A$563,F$3,Input_Konektivitas!$B$3:$B$563,$A4)) -> 6.5 | G4: =IF((COUNTIFS(Input_Konektivitas!$A$3:$A$563,$A4,Input_Konektivitas!$B$3:$B$563,G$3,Input_Konektivitas!$D$3:$D$563,">0")+COUNTIFS(Input_Konektivitas!$A$3:$A$563,G$3,Input_Konektivitas!$B$3:$B$563,$A4,Input_Konektivitas!$D$3:$D$563,">0"))=0,"",SUMIFS(Input_Konektivitas!$D$3:$D$563,Input_Konektivitas!$A$3:$A$563,$A4,Input_Konektivitas!$B$3:$B$563,G$3)+SUMIFS(Input_Konektivitas!$D$3:$D$563,Input_Konektivitas!$A$3:$A$563,G$3,Input_Konektivitas!$B$3:$B$563,$A4)) -> 4.8333 | H4: =IF((COUNTIFS(Input_Konektivitas!$A$3:$A$563,$A4,Input_Konektivitas!$B$3:$B$563,H$3,Input_Konektivitas!$D$3:$D$563,">0")+COUNTIFS(Input_Konektivitas!$A$3:$A$563,H$3,Input_Konektivitas!$B$3:$B$563,$A4,Input_Konektivitas!$D$3:$D$563,">0"))=0,"",SUMIFS(Input_Konektivitas!$D$3:$D$563,Input_Konektivitas!$A$3:$A$563,$A4,Input_Konektivitas!$B$3:$B$563,H$3)+SUMIFS(Input_Konektivitas!$D$3:$D$563,Input_Konektivitas!$A$3:$A$563,H$3,Input_Konektivitas!$B$3:$B$563,$A4)) -> 6.92 | I4: =IF((COUNTIFS(Input_Konektivitas!$A$3:$A$563,$A4,Input_Konektivitas!$B$3:$B$563,I$3,Input_Konektivitas!$D$3:$D$563,">0")+COUNTIFS(Input_Konektivitas!$A$3:$A$563,I$3,Input_Konektivitas!$B$3:$B$563,$A4,Input_Konektivitas!$D$3:$D$563,">0"))=0,"",SUMIFS(Input_Konektivitas!$D$3:$D$563,Input_Konektivitas!$A$3:$A$563,$A4,Input_Konektivitas!$B$3:$B$563,I$3)+SUMIFS(Input_Konektivitas!$D$3:$D$563,Input_Konektivitas!$A$3:$A$563,I$3,Input_Konektivitas!$B$3:$B$563,$A4)) -> 5.58 | J4: =IF((COUNTIFS(Input_Konektivitas!$A$3:$A$563,$A4,Input_Konektivitas!$B$3:$B$563,J$3,Input_Konektivitas!$D$3:$D$563,">0")+COUNTIFS(Input_Konektivitas!$A$3:$A$563,J$3,Input_Konektivitas!$B$3:$B$563,$A4,Input_Konektivitas!$D$3:$D$563,">0"))=0,"",SUMIFS(Input_Konektivitas!$D$3:$D$563,Input_Konektivitas!$A$3:$A$563,$A4,Input_Konektivitas!$B$3:$B$563,J$3)+SUMIFS(Input_Konektivitas!$D$3:$D$563,Input_Konektivitas!$A$3:$A$563,J$3,Input_Konektivitas!$B$3:$B$563,$A4)) -> 9.4167 | ... AI4: =IF((COUNTIFS(Input_Konektivitas!$A$3:$A$563,$A4,Input_Konektivitas!$B$3:$B$563,AI$3,Input_Konektivitas!$D$3:$D$563,">0")+COUNTIFS(Input_Konektivitas!$A$3:$A$563,AI$3,Input_Konektivitas!$B$3:$B$563,$A4,Input_Konektivitas!$D$3:$D$563,">0"))=0,"",SUMIFS(Input_Konektivitas!$D$3:$D$563,Input_Konektivitas!$A$3:$A$563,$A4,Input_Konektivitas!$B$3:$B$563,AI$3)+SUMIFS(Input_Konektivitas!$D$3:$D$563,Input_Konektivitas!$A$3:$A$563,AI$3,Input_Konektivitas!$B$3:$B$563,$A4)) -> 12.92
A5: Sumatera Utara | B5: =IF((COUNTIFS(Input_Konektivitas!$A$3:$A$563,$A5,Input_Konektivitas!$B$3:$B$563,B$3,Input_Konektivitas!$D$3:$D$563,">0")+COUNTIFS(Input_Konektivitas!$A$3:$A$563,B$3,Input_Konektivitas!$B$3:$B$563,$A5,Input_Konektivitas!$D$3:$D$563,">0"))=0,"",SUMIFS(Input_Konektivitas!$D$3:$D$563,Input_Konektivitas!$A$3:$A$563,$A5,Input_Konektivitas!$B$3:$B$563,B$3)+SUMIFS(Input_Konektivitas!$D$3:$D$563,Input_Konektivitas!$A$3:$A$563,B$3,Input_Konektivitas!$B$3:$B$563,$A5)) -> 1.583 | C5: 0 | D5: =IF((COUNTIFS(Input_Konektivitas!$A$3:$A$563,$A5,Input_Konektivitas!$B$3:$B$563,D$3,Input_Konektivitas!$D$3:$D$563,">0")+COUNTIFS(Input_Konektivitas!$A$3:$A$563,D$3,Input_Konektivitas!$B$3:$B$563,$A5,Input_Konektivitas!$D$3:$D$563,">0"))=0,"",SUMIFS(Input_Konektivitas!$D$3:$D$563,Input_Konektivitas!$A$3:$A$563,$A5,Input_Konektivitas!$B$3:$B$563,D$3)+SUMIFS(Input_Konektivitas!$D$3:$D$563,Input_Konektivitas!$A$3:$A$563,D$3,Input_Konektivitas!$B$3:$B$563,$A5)) -> 1.33 | E5: =IF((COUNTIFS(Input_Konektivitas!$A$3:$A$563,$A5,Input_Konektivitas!$B$3:$B$563,E$3,Input_Konektivitas!$D$3:$D$563,">0")+COUNTIFS(Input_Konektivitas!$A$3:$A$563,E$3,Input_Konektivitas!$B$3:$B$563,$A5,Input_Konektivitas!$D$3:$D$563,">0"))=0,"",SUMIFS(Input_Konektivitas!$D$3:$D$563,Input_Konektivitas!$A$3:$A$563,$A5,Input_Konektivitas!$B$3:$B$563,E$3)+SUMIFS(Input_Konektivitas!$D$3:$D$563,Input_Konektivitas!$A$3:$A$563,E$3,Input_Konektivitas!$B$3:$B$563,$A5)) -> 1.1667 | F5: =IF((COUNTIFS(Input_Konektivitas!$A$3:$A$563,$A5,Input_Konektivitas!$B$3:$B$563,F$3,Input_Konektivitas!$D$3:$D$563,">0")+COUNTIFS(Input_Konektivitas!$A$3:$A$563,F$3,Input_Konektivitas!$B$3:$B$563,$A5,Input_Konektivitas!$D$3:$D$563,">0"))=0,"",SUMIFS(Input_Konektivitas!$D$3:$D$563,Input_Konektivitas!$A$3:$A$563,$A5,Input_Konektivitas!$B$3:$B$563,F$3)+SUMIFS(Input_Konektivitas!$D$3:$D$563,Input_Konektivitas!$A$3:$A$563,F$3,Input_Konektivitas!$B$3:$B$563,$A5)) -> 4.42 | G5: =IF((COUNTIFS(Input_Konektivitas!$A$3:$A$563,$A5,Input_Konektivitas!$B$3:$B$563,G$3,Input_Konektivitas!$D$3:$D$563,">0")+COUNTIFS(Input_Konektivitas!$A$3:$A$563,G$3,Input_Konektivitas!$B$3:$B$563,$A5,Input_Konektivitas!$D$3:$D$563,">0"))=0,"",SUMIFS(Input_Konektivitas!$D$3:$D$563,Input_Konektivitas!$A$3:$A$563,$A5,Input_Konektivitas!$B$3:$B$563,G$3)+SUMIFS(Input_Konektivitas!$D$3:$D$563,Input_Konektivitas!$A$3:$A$563,G$3,Input_Konektivitas!$B$3:$B$563,$A5)) -> 1.833 | H5: =IF((COUNTIFS(Input_Konektivitas!$A$3:$A$563,$A5,Input_Konektivitas!$B$3:$B$563,H$3,Input_Konektivitas!$D$3:$D$563,">0")+COUNTIFS(Input_Konektivitas!$A$3:$A$563,H$3,Input_Konektivitas!$B$3:$B$563,$A5,Input_Konektivitas!$D$3:$D$563,">0"))=0,"",SUMIFS(Input_Konektivitas!$D$3:$D$563,Input_Konektivitas!$A$3:$A$563,$A5,Input_Konektivitas!$B$3:$B$563,H$3)+SUMIFS(Input_Konektivitas!$D$3:$D$563,Input_Konektivitas!$A$3:$A$563,H$3,Input_Konektivitas!$B$3:$B$563,$A5)) -> 5.1667 | I5: =IF((COUNTIFS(Input_Konektivitas!$A$3:$A$563,$A5,Input_Konektivitas!$B$3:$B$563,I$3,Input_Konektivitas!$D$3:$D$563,">0")+COUNTIFS(Input_Konektivitas!$A$3:$A$563,I$3,Input_Konektivitas!$B$3:$B$563,$A5,Input_Konektivitas!$D$3:$D$563,">0"))=0,"",SUMIFS(Input_Konektivitas!$D$3:$D$563,Input_Konektivitas!$A$3:$A$563,$A5,Input_Konektivitas!$B$3:$B$563,I$3)+SUMIFS(Input_Konektivitas!$D$3:$D$563,Input_Konektivitas!$A$3:$A$563,I$3,Input_Konektivitas!$B$3:$B$563,$A5)) -> 4.167 | J5: =IF((COUNTIFS(Input_Konektivitas!$A$3:$A$563,$A5,Input_Konektivitas!$B$3:$B$563,J$3,Input_Konektivitas!$D$3:$D$563,">0")+COUNTIFS(Input_Konektivitas!$A$3:$A$563,J$3,Input_Konektivitas!$B$3:$B$563,$A5,Input_Konektivitas!$D$3:$D$563,">0"))=0,"",SUMIFS(Input_Konektivitas!$D$3:$D$563,Input_Konektivitas!$A$3:$A$563,$A5,Input_Konektivitas!$B$3:$B$563,J$3)+SUMIFS(Input_Konektivitas!$D$3:$D$563,Input_Konektivitas!$A$3:$A$563,J$3,Input_Konektivitas!$B$3:$B$563,$A5)) -> 5.5 | K5: =IF((COUNTIFS(Input_Konektivitas!$A$3:$A$563,$A5,Input_Konektivitas!$B$3:$B$563,K$3,Input_Konektivitas!$D$3:$D$563,">0")+COUNTIFS(Input_Konektivitas!$A$3:$A$563,K$3,Input_Konektivitas!$B$3:$B$563,$A5,Input_Konektivitas!$D$3:$D$563,">0"))=0,"",SUMIFS(Input_Konektivitas!$D$3:$D$563,Input_Konektivitas!$A$3:$A$563,$A5,Input_Konektivitas!$B$3:$B$563,K$3)+SUMIFS(Input_Konektivitas!$D$3:$D$563,Input_Konektivitas!$A$3:$A$563,K$3,Input_Konektivitas!$B$3:$B$563,$A5)) -> 5.92 | ... AI5: =IF((COUNTIFS(Input_Konektivitas!$A$3:$A$563,$A5,Input_Konektivitas!$B$3:$B$563,AI$3,Input_Konektivitas!$D$3:$D$563,">0")+COUNTIFS(Input_Konektivitas!$A$3:$A$563,AI$3,Input_Konektivitas!$B$3:$B$563,$A5,Input_Konektivitas!$D$3:$D$563,">0"))=0,"",SUMIFS(Input_Konektivitas!$D$3:$D$563,Input_Konektivitas!$A$3:$A$563,$A5,Input_Konektivitas!$B$3:$B$563,AI$3)+SUMIFS(Input_Konektivitas!$D$3:$D$563,Input_Konektivitas!$A$3:$A$563,AI$3,Input_Konektivitas!$B$3:$B$563,$A5)) -> 8.75
A6: Sumatera Barat | B6: =IF((COUNTIFS(Input_Konektivitas!$A$3:$A$563,$A6,Input_Konektivitas!$B$3:$B$563,B$3,Input_Konektivitas!$D$3:$D$563,">0")+COUNTIFS(Input_Konektivitas!$A$3:$A$563,B$3,Input_Konektivitas!$B$3:$B$563,$A6,Input_Konektivitas!$D$3:$D$563,">0"))=0,"",SUMIFS(Input_Konektivitas!$D$3:$D$563,Input_Konektivitas!$A$3:$A$563,$A6,Input_Konektivitas!$B$3:$B$563,B$3)+SUMIFS(Input_Konektivitas!$D$3:$D$563,Input_Konektivitas!$A$3:$A$563,B$3,Input_Konektivitas!$B$3:$B$563,$A6)) -> 6.5 | C6: =IF((COUNTIFS(Input_Konektivitas!$A$3:$A$563,$A6,Input_Konektivitas!$B$3:$B$563,C$3,Input_Konektivitas!$D$3:$D$563,">0")+COUNTIFS(Input_Konektivitas!$A$3:$A$563,C$3,Input_Konektivitas!$B$3:$B$563,$A6,Input_Konektivitas!$D$3:$D$563,">0"))=0,"",SUMIFS(Input_Konektivitas!$D$3:$D$563,Input_Konektivitas!$A$3:$A$563,$A6,Input_Konektivitas!$B$3:$B$563,C$3)+SUMIFS(Input_Konektivitas!$D$3:$D$563,Input_Konektivitas!$A$3:$A$563,C$3,Input_Konektivitas!$B$3:$B$563,$A6)) -> 1.33 | D6: 0 | E6: =IF((COUNTIFS(Input_Konektivitas!$A$3:$A$563,$A6,Input_Konektivitas!$B$3:$B$563,E$3,Input_Konektivitas!$D$3:$D$563,">0")+COUNTIFS(Input_Konektivitas!$A$3:$A$563,E$3,Input_Konektivitas!$B$3:$B$563,$A6,Input_Konektivitas!$D$3:$D$563,">0"))=0,"",SUMIFS(Input_Konektivitas!$D$3:$D$563,Input_Konektivitas!$A$3:$A$563,$A6,Input_Konektivitas!$B$3:$B$563,E$3)+SUMIFS(Input_Konektivitas!$D$3:$D$563,Input_Konektivitas!$A$3:$A$563,E$3,Input_Konektivitas!$B$3:$B$563,$A6)) -> 11.75 | F6: =IF((COUNTIFS(Input_Konektivitas!$A$3:$A$563,$A6,Input_Konektivitas!$B$3:$B$563,F$3,Input_Konektivitas!$D$3:$D$563,">0")+COUNTIFS(Input_Konektivitas!$A$3:$A$563,F$3,Input_Konektivitas!$B$3:$B$563,$A6,Input_Konektivitas!$D$3:$D$563,">0"))=0,"",SUMIFS(Input_Konektivitas!$D$3:$D$563,Input_Konektivitas!$A$3:$A$563,$A6,Input_Konektivitas!$B$3:$B$563,F$3)+SUMIFS(Input_Konektivitas!$D$3:$D$563,Input_Konektivitas!$A$3:$A$563,F$3,Input_Konektivitas!$B$3:$B$563,$A6)) -> 4.42 | G6: =IF((COUNTIFS(Input_Konektivitas!$A$3:$A$563,$A6,Input_Konektivitas!$B$3:$B$563,G$3,Input_Konektivitas!$D$3:$D$563,">0")+COUNTIFS(Input_Konektivitas!$A$3:$A$563,G$3,Input_Konektivitas!$B$3:$B$563,$A6,Input_Konektivitas!$D$3:$D$563,">0"))=0,"",SUMIFS(Input_Konektivitas!$D$3:$D$563,Input_Konektivitas!$A$3:$A$563,$A6,Input_Konektivitas!$B$3:$B$563,G$3)+SUMIFS(Input_Konektivitas!$D$3:$D$563,Input_Konektivitas!$A$3:$A$563,G$3,Input_Konektivitas!$B$3:$B$563,$A6)) -> 4 | H6: =IF((COUNTIFS(Input_Konektivitas!$A$3:$A$563,$A6,Input_Konektivitas!$B$3:$B$563,H$3,Input_Konektivitas!$D$3:$D$563,">0")+COUNTIFS(Input_Konektivitas!$A$3:$A$563,H$3,Input_Konektivitas!$B$3:$B$563,$A6,Input_Konektivitas!$D$3:$D$563,">0"))=0,"",SUMIFS(Input_Konektivitas!$D$3:$D$563,Input_Konektivitas!$A$3:$A$563,$A6,Input_Konektivitas!$B$3:$B$563,H$3)+SUMIFS(Input_Konektivitas!$D$3:$D$563,Input_Konektivitas!$A$3:$A$563,H$3,Input_Konektivitas!$B$3:$B$563,$A6)) -> 5.33 | I6: =IF((COUNTIFS(Input_Konektivitas!$A$3:$A$563,$A6,Input_Konektivitas!$B$3:$B$563,I$3,Input_Konektivitas!$D$3:$D$563,">0")+COUNTIFS(Input_Konektivitas!$A$3:$A$563,I$3,Input_Konektivitas!$B$3:$B$563,$A6,Input_Konektivitas!$D$3:$D$563,">0"))=0,"",SUMIFS(Input_Konektivitas!$D$3:$D$563,Input_Konektivitas!$A$3:$A$563,$A6,Input_Konektivitas!$B$3:$B$563,I$3)+SUMIFS(Input_Konektivitas!$D$3:$D$563,Input_Konektivitas!$A$3:$A$563,I$3,Input_Konektivitas!$B$3:$B$563,$A6)) -> 4.833 | J6: =IF((COUNTIFS(Input_Konektivitas!$A$3:$A$563,$A6,Input_Konektivitas!$B$3:$B$563,J$3,Input_Konektivitas!$D$3:$D$563,">0")+COUNTIFS(Input_Konektivitas!$A$3:$A$563,J$3,Input_Konektivitas!$B$3:$B$563,$A6,Input_Konektivitas!$D$3:$D$563,">0"))=0,"",SUMIFS(Input_Konektivitas!$D$3:$D$563,Input_Konektivitas!$A$3:$A$563,$A6,Input_Konektivitas!$B$3:$B$563,J$3)+SUMIFS(Input_Konektivitas!$D$3:$D$563,Input_Konektivitas!$A$3:$A$563,J$3,Input_Konektivitas!$B$3:$B$563,$A6)) -> 4.833 | K6: =IF((COUNTIFS(Input_Konektivitas!$A$3:$A$563,$A6,Input_Konektivitas!$B$3:$B$563,K$3,Input_Konektivitas!$D$3:$D$563,">0")+COUNTIFS(Input_Konektivitas!$A$3:$A$563,K$3,Input_Konektivitas!$B$3:$B$563,$A6,Input_Konektivitas!$D$3:$D$563,">0"))=0,"",SUMIFS(Input_Konektivitas!$D$3:$D$563,Input_Konektivitas!$A$3:$A$563,$A6,Input_Konektivitas!$B$3:$B$563,K$3)+SUMIFS(Input_Konektivitas!$D$3:$D$563,Input_Konektivitas!$A$3:$A$563,K$3,Input_Konektivitas!$B$3:$B$563,$A6)) -> 5 | L6: =IF((COUNTIFS(Input_Konektivitas!$A$3:$A$563,$A6,Input_Konektivitas!$B$3:$B$563,L$3,Input_Konektivitas!$D$3:$D$563,">0")+COUNTIFS(Input_Konektivitas!$A$3:$A$563,L$3,Input_Konektivitas!$B$3:$B$563,$A6,Input_Konektivitas!$D$3:$D$563,">0"))=0,"",SUMIFS(Input_Konektivitas!$D$3:$D$563,Input_Konektivitas!$A$3:$A$563,$A6,Input_Konektivitas!$B$3:$B$563,L$3)+SUMIFS(Input_Konektivitas!$D$3:$D$563,Input_Konektivitas!$A$3:$A$563,L$3,Input_Konektivitas!$B$3:$B$563,$A6)) -> 1.83 | ... AI6: =IF((COUNTIFS(Input_Konektivitas!$A$3:$A$563,$A6,Input_Konektivitas!$B$3:$B$563,AI$3,Input_Konektivitas!$D$3:$D$563,">0")+COUNTIFS(Input_Konektivitas!$A$3:$A$563,AI$3,Input_Konektivitas!$B$3:$B$563,$A6,Input_Konektivitas!$D$3:$D$563,">0"))=0,"",SUMIFS(Input_Konektivitas!$D$3:$D$563,Input_Konektivitas!$A$3:$A$563,$A6,Input_Konektivitas!$B$3:$B$563,AI$3)+SUMIFS(Input_Konektivitas!$D$3:$D$563,Input_Konektivitas!$A$3:$A$563,AI$3,Input_Konektivitas!$B$3:$B$563,$A6)) -> 10.42
A7: Riau | B7: =IF((COUNTIFS(Input_Konektivitas!$A$3:$A$563,$A7,Input_Konektivitas!$B$3:$B$563,B$3,Input_Konektivitas!$D$3:$D$563,">0")+COUNTIFS(Input_Konektivitas!$A$3:$A$563,B$3,Input_Konektivitas!$B$3:$B$563,$A7,Input_Konektivitas!$D$3:$D$563,">0"))=0,"",SUMIFS(Input_Konektivitas!$D$3:$D$563,Input_Konektivitas!$A$3:$A$563,$A7,Input_Konektivitas!$B$3:$B$563,B$3)+SUMIFS(Input_Konektivitas!$D$3:$D$563,Input_Konektivitas!$A$3:$A$563,B$3,Input_Konektivitas!$B$3:$B$563,$A7)) -> 3.5 | C7: =IF((COUNTIFS(Input_Konektivitas!$A$3:$A$563,$A7,Input_Konektivitas!$B$3:$B$563,C$3,Input_Konektivitas!$D$3:$D$563,">0")+COUNTIFS(Input_Konektivitas!$A$3:$A$563,C$3,Input_Konektivitas!$B$3:$B$563,$A7,Input_Konektivitas!$D$3:$D$563,">0"))=0,"",SUMIFS(Input_Konektivitas!$D$3:$D$563,Input_Konektivitas!$A$3:$A$563,$A7,Input_Konektivitas!$B$3:$B$563,C$3)+SUMIFS(Input_Konektivitas!$D$3:$D$563,Input_Konektivitas!$A$3:$A$563,C$3,Input_Konektivitas!$B$3:$B$563,$A7)) -> 1.1667 | D7: =IF((COUNTIFS(Input_Konektivitas!$A$3:$A$563,$A7,Input_Konektivitas!$B$3:$B$563,D$3,Input_Konektivitas!$D$3:$D$563,">0")+COUNTIFS(Input_Konektivitas!$A$3:$A$563,D$3,Input_Konektivitas!$B$3:$B$563,$A7,Input_Konektivitas!$D$3:$D$563,">0"))=0,"",SUMIFS(Input_Konektivitas!$D$3:$D$563,Input_Konektivitas!$A$3:$A$563,$A7,Input_Konektivitas!$B$3:$B$563,D$3)+SUMIFS(Input_Konektivitas!$D$3:$D$563,Input_Konektivitas!$A$3:$A$563,D$3,Input_Konektivitas!$B$3:$B$563,$A7)) -> 11.75 | E7: 0 | F7: =IF((COUNTIFS(Input_Konektivitas!$A$3:$A$563,$A7,Input_Konektivitas!$B$3:$B$563,F$3,Input_Konektivitas!$D$3:$D$563,">0")+COUNTIFS(Input_Konektivitas!$A$3:$A$563,F$3,Input_Konektivitas!$B$3:$B$563,$A7,Input_Konektivitas!$D$3:$D$563,">0"))=0,"",SUMIFS(Input_Konektivitas!$D$3:$D$563,Input_Konektivitas!$A$3:$A$563,$A7,Input_Konektivitas!$B$3:$B$563,F$3)+SUMIFS(Input_Konektivitas!$D$3:$D$563,Input_Konektivitas!$A$3:$A$563,F$3,Input_Konektivitas!$B$3:$B$563,$A7)) -> 4.167 | G7: =IF((COUNTIFS(Input_Konektivitas!$A$3:$A$563,$A7,Input_Konektivitas!$B$3:$B$563,G$3,Input_Konektivitas!$D$3:$D$563,">0")+COUNTIFS(Input_Konektivitas!$A$3:$A$563,G$3,Input_Konektivitas!$B$3:$B$563,$A7,Input_Konektivitas!$D$3:$D$563,">0"))=0,"",SUMIFS(Input_Konektivitas!$D$3:$D$563,Input_Konektivitas!$A$3:$A$563,$A7,Input_Konektivitas!$B$3:$B$563,G$3)+SUMIFS(Input_Konektivitas!$D$3:$D$563,Input_Konektivitas!$A$3:$A$563,G$3,Input_Konektivitas!$B$3:$B$563,$A7)) -> 3.58 | H7: =IF((COUNTIFS(Input_Konektivitas!$A$3:$A$563,$A7,Input_Konektivitas!$B$3:$B$563,H$3,Input_Konektivitas!$D$3:$D$563,">0")+COUNTIFS(Input_Konektivitas!$A$3:$A$563,H$3,Input_Konektivitas!$B$3:$B$563,$A7,Input_Konektivitas!$D$3:$D$563,">0"))=0,"",SUMIFS(Input_Konektivitas!$D$3:$D$563,Input_Konektivitas!$A$3:$A$563,$A7,Input_Konektivitas!$B$3:$B$563,H$3)+SUMIFS(Input_Konektivitas!$D$3:$D$563,Input_Konektivitas!$A$3:$A$563,H$3,Input_Konektivitas!$B$3:$B$563,$A7)) -> 4.83 | I7: =IF((COUNTIFS(Input_Konektivitas!$A$3:$A$563,$A7,Input_Konektivitas!$B$3:$B$563,I$3,Input_Konektivitas!$D$3:$D$563,">0")+COUNTIFS(Input_Konektivitas!$A$3:$A$563,I$3,Input_Konektivitas!$B$3:$B$563,$A7,Input_Konektivitas!$D$3:$D$563,">0"))=0,"",SUMIFS(Input_Konektivitas!$D$3:$D$563,Input_Konektivitas!$A$3:$A$563,$A7,Input_Konektivitas!$B$3:$B$563,I$3)+SUMIFS(Input_Konektivitas!$D$3:$D$563,Input_Konektivitas!$A$3:$A$563,I$3,Input_Konektivitas!$B$3:$B$563,$A7)) -> 3.75 | J7: =IF((COUNTIFS(Input_Konektivitas!$A$3:$A$563,$A7,Input_Konektivitas!$B$3:$B$563,J$3,Input_Konektivitas!$D$3:$D$563,">0")+COUNTIFS(Input_Konektivitas!$A$3:$A$563,J$3,Input_Konektivitas!$B$3:$B$563,$A7,Input_Konektivitas!$D$3:$D$563,">0"))=0,"",SUMIFS(Input_Konektivitas!$D$3:$D$563,Input_Konektivitas!$A$3:$A$563,$A7,Input_Konektivitas!$B$3:$B$563,J$3)+SUMIFS(Input_Konektivitas!$D$3:$D$563,Input_Konektivitas!$A$3:$A$563,J$3,Input_Konektivitas!$B$3:$B$563,$A7)) -> 5.5 | K7: =IF((COUNTIFS(Input_Konektivitas!$A$3:$A$563,$A7,Input_Konektivitas!$B$3:$B$563,K$3,Input_Konektivitas!$D$3:$D$563,">0")+COUNTIFS(Input_Konektivitas!$A$3:$A$563,K$3,Input_Konektivitas!$B$3:$B$563,$A7,Input_Konektivitas!$D$3:$D$563,">0"))=0,"",SUMIFS(Input_Konektivitas!$D$3:$D$563,Input_Konektivitas!$A$3:$A$563,$A7,Input_Konektivitas!$B$3:$B$563,K$3)+SUMIFS(Input_Konektivitas!$D$3:$D$563,Input_Konektivitas!$A$3:$A$563,K$3,Input_Konektivitas!$B$3:$B$563,$A7)) -> 5.92 | L7: =IF((COUNTIFS(Input_Konektivitas!$A$3:$A$563,$A7,Input_Konektivitas!$B$3:$B$563,L$3,Input_Konektivitas!$D$3:$D$563,">0")+COUNTIFS(Input_Konektivitas!$A$3:$A$563,L$3,Input_Konektivitas!$B$3:$B$563,$A7,Input_Konektivitas!$D$3:$D$563,">0"))=0,"",SUMIFS(Input_Konektivitas!$D$3:$D$563,Input_Konektivitas!$A$3:$A$563,$A7,Input_Konektivitas!$B$3:$B$563,L$3)+SUMIFS(Input_Konektivitas!$D$3:$D$563,Input_Konektivitas!$A$3:$A$563,L$3,Input_Konektivitas!$B$3:$B$563,$A7)) -> 1.75 | M7: =IF((COUNTIFS(Input_Konektivitas!$A$3:$A$563,$A7,Input_Konektivitas!$B$3:$B$563,M$3,Input_Konektivitas!$D$3:$D$563,">0")+COUNTIFS(Input_Konektivitas!$A$3:$A$563,M$3,Input_Konektivitas!$B$3:$B$563,$A7,Input_Konektivitas!$D$3:$D$563,">0"))=0,"",SUMIFS(Input_Konektivitas!$D$3:$D$563,Input_Konektivitas!$A$3:$A$563,$A7,Input_Konektivitas!$B$3:$B$563,M$3)+SUMIFS(Input_Konektivitas!$D$3:$D$563,Input_Konektivitas!$A$3:$A$563,M$3,Input_Konektivitas!$B$3:$B$563,$A7)) -> 6.33 | ... AI7: =IF((COUNTIFS(Input_Konektivitas!$A$3:$A$563,$A7,Input_Konektivitas!$B$3:$B$563,AI$3,Input_Konektivitas!$D$3:$D$563,">0")+COUNTIFS(Input_Konektivitas!$A$3:$A$563,AI$3,Input_Konektivitas!$B$3:$B$563,$A7,Input_Konektivitas!$D$3:$D$563,">0"))=0,"",SUMIFS(Input_Konektivitas!$D$3:$D$563,Input_Konektivitas!$A$3:$A$563,$A7,Input_Konektivitas!$B$3:$B$563,AI$3)+SUMIFS(Input_Konektivitas!$D$3:$D$563,Input_Konektivitas!$A$3:$A$563,AI$3,Input_Konektivitas!$B$3:$B$563,$A7)) -> 10.83
A8: Jambi | B8: =IF((COUNTIFS(Input_Konektivitas!$A$3:$A$563,$A8,Input_Konektivitas!$B$3:$B$563,B$3,Input_Konektivitas!$D$3:$D$563,">0")+COUNTIFS(Input_Konektivitas!$A$3:$A$563,B$3,Input_Konektivitas!$B$3:$B$563,$A8,Input_Konektivitas!$D$3:$D$563,">0"))=0,"",SUMIFS(Input_Konektivitas!$D$3:$D$563,Input_Konektivitas!$A$3:$A$563,$A8,Input_Konektivitas!$B$3:$B$563,B$3)+SUMIFS(Input_Konektivitas!$D$3:$D$563,Input_Konektivitas!$A$3:$A$563,B$3,Input_Konektivitas!$B$3:$B$563,$A8)) -> 6.5 | C8: =IF((COUNTIFS(Input_Konektivitas!$A$3:$A$563,$A8,Input_Konektivitas!$B$3:$B$563,C$3,Input_Konektivitas!$D$3:$D$563,">0")+COUNTIFS(Input_Konektivitas!$A$3:$A$563,C$3,Input_Konektivitas!$B$3:$B$563,$A8,Input_Konektivitas!$D$3:$D$563,">0"))=0,"",SUMIFS(Input_Konektivitas!$D$3:$D$563,Input_Konektivitas!$A$3:$A$563,$A8,Input_Konektivitas!$B$3:$B$563,C$3)+SUMIFS(Input_Konektivitas!$D$3:$D$563,Input_Konektivitas!$A$3:$A$563,C$3,Input_Konektivitas!$B$3:$B$563,$A8)) -> 4.42 | D8: =IF((COUNTIFS(Input_Konektivitas!$A$3:$A$563,$A8,Input_Konektivitas!$B$3:$B$563,D$3,Input_Konektivitas!$D$3:$D$563,">0")+COUNTIFS(Input_Konektivitas!$A$3:$A$563,D$3,Input_Konektivitas!$B$3:$B$563,$A8,Input_Konektivitas!$D$3:$D$563,">0"))=0,"",SUMIFS(Input_Konektivitas!$D$3:$D$563,Input_Konektivitas!$A$3:$A$563,$A8,Input_Konektivitas!$B$3:$B$563,D$3)+SUMIFS(Input_Konektivitas!$D$3:$D$563,Input_Konektivitas!$A$3:$A$563,D$3,Input_Konektivitas!$B$3:$B$563,$A8)) -> 4.42 | E8: =IF((COUNTIFS(Input_Konektivitas!$A$3:$A$563,$A8,Input_Konektivitas!$B$3:$B$563,E$3,Input_Konektivitas!$D$3:$D$563,">0")+COUNTIFS(Input_Konektivitas!$A$3:$A$563,E$3,Input_Konektivitas!$B$3:$B$563,$A8,Input_Konektivitas!$D$3:$D$563,">0"))=0,"",SUMIFS(Input_Konektivitas!$D$3:$D$563,Input_Konektivitas!$A$3:$A$563,$A8,Input_Konektivitas!$B$3:$B$563,E$3)+SUMIFS(Input_Konektivitas!$D$3:$D$563,Input_Konektivitas!$A$3:$A$563,E$3,Input_Konektivitas!$B$3:$B$563,$A8)) -> 4.167 | F8: 0 | G8: =IF((COUNTIFS(Input_Konektivitas!$A$3:$A$563,$A8,Input_Konektivitas!$B$3:$B$563,G$3,Input_Konektivitas!$D$3:$D$563,">0")+COUNTIFS(Input_Konektivitas!$A$3:$A$563,G$3,Input_Konektivitas!$B$3:$B$563,$A8,Input_Konektivitas!$D$3:$D$563,">0"))=0,"",SUMIFS(Input_Konektivitas!$D$3:$D$563,Input_Konektivitas!$A$3:$A$563,$A8,Input_Konektivitas!$B$3:$B$563,G$3)+SUMIFS(Input_Konektivitas!$D$3:$D$563,Input_Konektivitas!$A$3:$A$563,G$3,Input_Konektivitas!$B$3:$B$563,$A8)) -> 3.83 | H8: =IF((COUNTIFS(Input_Konektivitas!$A$3:$A$563,$A8,Input_Konektivitas!$B$3:$B$563,H$3,Input_Konektivitas!$D$3:$D$563,">0")+COUNTIFS(Input_Konektivitas!$A$3:$A$563,H$3,Input_Konektivitas!$B$3:$B$563,$A8,Input_Konektivitas!$D$3:$D$563,">0"))=0,"",SUMIFS(Input_Konektivitas!$D$3:$D$563,Input_Konektivitas!$A$3:$A$563,$A8,Input_Konektivitas!$B$3:$B$563,H$3)+SUMIFS(Input_Konektivitas!$D$3:$D$563,Input_Konektivitas!$A$3:$A$563,H$3,Input_Konektivitas!$B$3:$B$563,$A8)) -> 5 | I8: =IF((COUNTIFS(Input_Konektivitas!$A$3:$A$563,$A8,Input_Konektivitas!$B$3:$B$563,I$3,Input_Konektivitas!$D$3:$D$563,">0")+COUNTIFS(Input_Konektivitas!$A$3:$A$563,I$3,Input_Konektivitas!$B$3:$B$563,$A8,Input_Konektivitas!$D$3:$D$563,">0"))=0,"",SUMIFS(Input_Konektivitas!$D$3:$D$563,Input_Konektivitas!$A$3:$A$563,$A8,Input_Konektivitas!$B$3:$B$563,I$3)+SUMIFS(Input_Konektivitas!$D$3:$D$563,Input_Konektivitas!$A$3:$A$563,I$3,Input_Konektivitas!$B$3:$B$563,$A8)) -> 3.75 | J8: =IF((COUNTIFS(Input_Konektivitas!$A$3:$A$563,$A8,Input_Konektivitas!$B$3:$B$563,J$3,Input_Konektivitas!$D$3:$D$563,">0")+COUNTIFS(Input_Konektivitas!$A$3:$A$563,J$3,Input_Konektivitas!$B$3:$B$563,$A8,Input_Konektivitas!$D$3:$D$563,">0"))=0,"",SUMIFS(Input_Konektivitas!$D$3:$D$563,Input_Konektivitas!$A$3:$A$563,$A8,Input_Konektivitas!$B$3:$B$563,J$3)+SUMIFS(Input_Konektivitas!$D$3:$D$563,Input_Konektivitas!$A$3:$A$563,J$3,Input_Konektivitas!$B$3:$B$563,$A8)) -> 4 | K8: =IF((COUNTIFS(Input_Konektivitas!$A$3:$A$563,$A8,Input_Konektivitas!$B$3:$B$563,K$3,Input_Konektivitas!$D$3:$D$563,">0")+COUNTIFS(Input_Konektivitas!$A$3:$A$563,K$3,Input_Konektivitas!$B$3:$B$563,$A8,Input_Konektivitas!$D$3:$D$563,">0"))=0,"",SUMIFS(Input_Konektivitas!$D$3:$D$563,Input_Konektivitas!$A$3:$A$563,$A8,Input_Konektivitas!$B$3:$B$563,K$3)+SUMIFS(Input_Konektivitas!$D$3:$D$563,Input_Konektivitas!$A$3:$A$563,K$3,Input_Konektivitas!$B$3:$B$563,$A8)) -> 5 | L8: =IF((COUNTIFS(Input_Konektivitas!$A$3:$A$563,$A8,Input_Konektivitas!$B$3:$B$563,L$3,Input_Konektivitas!$D$3:$D$563,">0")+COUNTIFS(Input_Konektivitas!$A$3:$A$563,L$3,Input_Konektivitas!$B$3:$B$563,$A8,Input_Konektivitas!$D$3:$D$563,">0"))=0,"",SUMIFS(Input_Konektivitas!$D$3:$D$563,Input_Konektivitas!$A$3:$A$563,$A8,Input_Konektivitas!$B$3:$B$563,L$3)+SUMIFS(Input_Konektivitas!$D$3:$D$563,Input_Konektivitas!$A$3:$A$563,L$3,Input_Konektivitas!$B$3:$B$563,$A8)) -> 1.33 | M8: =IF((COUNTIFS(Input_Konektivitas!$A$3:$A$563,$A8,Input_Konektivitas!$B$3:$B$563,M$3,Input_Konektivitas!$D$3:$D$563,">0")+COUNTIFS(Input_Konektivitas!$A$3:$A$563,M$3,Input_Konektivitas!$B$3:$B$563,$A8,Input_Konektivitas!$D$3:$D$563,">0"))=0,"",SUMIFS(Input_Konektivitas!$D$3:$D$563,Input_Konektivitas!$A$3:$A$563,$A8,Input_Konektivitas!$B$3:$B$563,M$3)+SUMIFS(Input_Konektivitas!$D$3:$D$563,Input_Konektivitas!$A$3:$A$563,M$3,Input_Konektivitas!$B$3:$B$563,$A8)) | N8: =IF((COUNTIFS(Input_Konektivitas!$A$3:$A$563,$A8,Input_Konektivitas!$B$3:$B$563,N$3,Input_Konektivitas!$D$3:$D$563,">0")+COUNTIFS(Input_Konektivitas!$A$3:$A$563,N$3,Input_Konektivitas!$B$3:$B$563,$A8,Input_Konektivitas!$D$3:$D$563,">0"))=0,"",SUMIFS(Input_Konektivitas!$D$3:$D$563,Input_Konektivitas!$A$3:$A$563,$A8,Input_Konektivitas!$B$3:$B$563,N$3)+SUMIFS(Input_Konektivitas!$D$3:$D$563,Input_Konektivitas!$A$3:$A$563,N$3,Input_Konektivitas!$B$3:$B$563,$A8)) -> 3.167 | ... AI8: =IF((COUNTIFS(Input_Konektivitas!$A$3:$A$563,$A8,Input_Konektivitas!$B$3:$B$563,AI$3,Input_Konektivitas!$D$3:$D$563,">0")+COUNTIFS(Input_Konektivitas!$A$3:$A$563,AI$3,Input_Konektivitas!$B$3:$B$563,$A8,Input_Konektivitas!$D$3:$D$563,">0"))=0,"",SUMIFS(Input_Konektivitas!$D$3:$D$563,Input_Konektivitas!$A$3:$A$563,$A8,Input_Konektivitas!$B$3:$B$563,AI$3)+SUMIFS(Input_Konektivitas!$D$3:$D$563,Input_Konektivitas!$A$3:$A$563,AI$3,Input_Konektivitas!$B$3:$B$563,$A8)) -> 9.83
A9: Sumatera Selatan | B9: =IF((COUNTIFS(Input_Konektivitas!$A$3:$A$563,$A9,Input_Konektivitas!$B$3:$B$563,B$3,Input_Konektivitas!$D$3:$D$563,">0")+COUNTIFS(Input_Konektivitas!$A$3:$A$563,B$3,Input_Konektivitas!$B$3:$B$563,$A9,Input_Konektivitas!$D$3:$D$563,">0"))=0,"",SUMIFS(Input_Konektivitas!$D$3:$D$563,Input_Konektivitas!$A$3:$A$563,$A9,Input_Konektivitas!$B$3:$B$563,B$3)+SUMIFS(Input_Konektivitas!$D$3:$D$563,Input_Konektivitas!$A$3:$A$563,B$3,Input_Konektivitas!$B$3:$B$563,$A9)) -> 4.8333 | C9: =IF((COUNTIFS(Input_Konektivitas!$A$3:$A$563,$A9,Input_Konektivitas!$B$3:$B$563,C$3,Input_Konektivitas!$D$3:$D$563,">0")+COUNTIFS(Input_Konektivitas!$A$3:$A$563,C$3,Input_Konektivitas!$B$3:$B$563,$A9,Input_Konektivitas!$D$3:$D$563,">0"))=0,"",SUMIFS(Input_Konektivitas!$D$3:$D$563,Input_Konektivitas!$A$3:$A$563,$A9,Input_Konektivitas!$B$3:$B$563,C$3)+SUMIFS(Input_Konektivitas!$D$3:$D$563,Input_Konektivitas!$A$3:$A$563,C$3,Input_Konektivitas!$B$3:$B$563,$A9)) -> 1.833 | D9: =IF((COUNTIFS(Input_Konektivitas!$A$3:$A$563,$A9,Input_Konektivitas!$B$3:$B$563,D$3,Input_Konektivitas!$D$3:$D$563,">0")+COUNTIFS(Input_Konektivitas!$A$3:$A$563,D$3,Input_Konektivitas!$B$3:$B$563,$A9,Input_Konektivitas!$D$3:$D$563,">0"))=0,"",SUMIFS(Input_Konektivitas!$D$3:$D$563,Input_Konektivitas!$A$3:$A$563,$A9,Input_Konektivitas!$B$3:$B$563,D$3)+SUMIFS(Input_Konektivitas!$D$3:$D$563,Input_Konektivitas!$A$3:$A$563,D$3,Input_Konektivitas!$B$3:$B$563,$A9)) -> 4 | E9: =IF((COUNTIFS(Input_Konektivitas!$A$3:$A$563,$A9,Input_Konektivitas!$B$3:$B$563,E$3,Input_Konektivitas!$D$3:$D$563,">0")+COUNTIFS(Input_Konektivitas!$A$3:$A$563,E$3,Input_Konektivitas!$B$3:$B$563,$A9,Input_Konektivitas!$D$3:$D$563,">0"))=0,"",SUMIFS(Input_Konektivitas!$D$3:$D$563,Input_Konektivitas!$A$3:$A$563,$A9,Input_Konektivitas!$B$3:$B$563,E$3)+SUMIFS(Input_Konektivitas!$D$3:$D$563,Input_Konektivitas!$A$3:$A$563,E$3,Input_Konektivitas!$B$3:$B$563,$A9)) -> 3.58 | F9: =IF((COUNTIFS(Input_Konektivitas!$A$3:$A$563,$A9,Input_Konektivitas!$B$3:$B$563,F$3,Input_Konektivitas!$D$3:$D$563,">0")+COUNTIFS(Input_Konektivitas!$A$3:$A$563,F$3,Input_Konektivitas!$B$3:$B$563,$A9,Input_Konektivitas!$D$3:$D$563,">0"))=0,"",SUMIFS(Input_Konektivitas!$D$3:$D$563,Input_Konektivitas!$A$3:$A$563,$A9,Input_Konektivitas!$B$3:$B$563,F$3)+SUMIFS(Input_Konektivitas!$D$3:$D$563,Input_Konektivitas!$A$3:$A$563,F$3,Input_Konektivitas!$B$3:$B$563,$A9)) -> 3.83 | G9: 0 | H9: =IF((COUNTIFS(Input_Konektivitas!$A$3:$A$563,$A9,Input_Konektivitas!$B$3:$B$563,H$3,Input_Konektivitas!$D$3:$D$563,">0")+COUNTIFS(Input_Konektivitas!$A$3:$A$563,H$3,Input_Konektivitas!$B$3:$B$563,$A9,Input_Konektivitas!$D$3:$D$563,">0"))=0,"",SUMIFS(Input_Konektivitas!$D$3:$D$563,Input_Konektivitas!$A$3:$A$563,$A9,Input_Konektivitas!$B$3:$B$563,H$3)+SUMIFS(Input_Konektivitas!$D$3:$D$563,Input_Konektivitas!$A$3:$A$563,H$3,Input_Konektivitas!$B$3:$B$563,$A9)) -> 4 | I9: =IF((COUNTIFS(Input_Konektivitas!$A$3:$A$563,$A9,Input_Konektivitas!$B$3:$B$563,I$3,Input_Konektivitas!$D$3:$D$563,">0")+COUNTIFS(Input_Konektivitas!$A$3:$A$563,I$3,Input_Konektivitas!$B$3:$B$563,$A9,Input_Konektivitas!$D$3:$D$563,">0"))=0,"",SUMIFS(Input_Konektivitas!$D$3:$D$563,Input_Konektivitas!$A$3:$A$563,$A9,Input_Konektivitas!$B$3:$B$563,I$3)+SUMIFS(Input_Konektivitas!$D$3:$D$563,Input_Konektivitas!$A$3:$A$563,I$3,Input_Konektivitas!$B$3:$B$563,$A9)) -> 2.92 | J9: =IF((COUNTIFS(Input_Konektivitas!$A$3:$A$563,$A9,Input_Konektivitas!$B$3:$B$563,J$3,Input_Konektivitas!$D$3:$D$563,">0")+COUNTIFS(Input_Konektivitas!$A$3:$A$563,J$3,Input_Konektivitas!$B$3:$B$563,$A9,Input_Konektivitas!$D$3:$D$563,">0"))=0,"",SUMIFS(Input_Konektivitas!$D$3:$D$563,Input_Konektivitas!$A$3:$A$563,$A9,Input_Konektivitas!$B$3:$B$563,J$3)+SUMIFS(Input_Konektivitas!$D$3:$D$563,Input_Konektivitas!$A$3:$A$563,J$3,Input_Konektivitas!$B$3:$B$563,$A9)) -> 0.75 | K9: =IF((COUNTIFS(Input_Konektivitas!$A$3:$A$563,$A9,Input_Konektivitas!$B$3:$B$563,K$3,Input_Konektivitas!$D$3:$D$563,">0")+COUNTIFS(Input_Konektivitas!$A$3:$A$563,K$3,Input_Konektivitas!$B$3:$B$563,$A9,Input_Konektivitas!$D$3:$D$563,">0"))=0,"",SUMIFS(Input_Konektivitas!$D$3:$D$563,Input_Konektivitas!$A$3:$A$563,$A9,Input_Konektivitas!$B$3:$B$563,K$3)+SUMIFS(Input_Konektivitas!$D$3:$D$563,Input_Konektivitas!$A$3:$A$563,K$3,Input_Konektivitas!$B$3:$B$563,$A9)) -> 2.75 | L9: =IF((COUNTIFS(Input_Konektivitas!$A$3:$A$563,$A9,Input_Konektivitas!$B$3:$B$563,L$3,Input_Konektivitas!$D$3:$D$563,">0")+COUNTIFS(Input_Konektivitas!$A$3:$A$563,L$3,Input_Konektivitas!$B$3:$B$563,$A9,Input_Konektivitas!$D$3:$D$563,">0"))=0,"",SUMIFS(Input_Konektivitas!$D$3:$D$563,Input_Konektivitas!$A$3:$A$563,$A9,Input_Konektivitas!$B$3:$B$563,L$3)+SUMIFS(Input_Konektivitas!$D$3:$D$563,Input_Konektivitas!$A$3:$A$563,L$3,Input_Konektivitas!$B$3:$B$563,$A9)) -> 1.167 | M9: =IF((COUNTIFS(Input_Konektivitas!$A$3:$A$563,$A9,Input_Konektivitas!$B$3:$B$563,M$3,Input_Konektivitas!$D$3:$D$563,">0")+COUNTIFS(Input_Konektivitas!$A$3:$A$563,M$3,Input_Konektivitas!$B$3:$B$563,$A9,Input_Konektivitas!$D$3:$D$563,">0"))=0,"",SUMIFS(Input_Konektivitas!$D$3:$D$563,Input_Konektivitas!$A$3:$A$563,$A9,Input_Konektivitas!$B$3:$B$563,M$3)+SUMIFS(Input_Konektivitas!$D$3:$D$563,Input_Konektivitas!$A$3:$A$563,M$3,Input_Konektivitas!$B$3:$B$563,$A9)) -> 6.5 | N9: =IF((COUNTIFS(Input_Konektivitas!$A$3:$A$563,$A9,Input_Konektivitas!$B$3:$B$563,N$3,Input_Konektivitas!$D$3:$D$563,">0")+COUNTIFS(Input_Konektivitas!$A$3:$A$563,N$3,Input_Konektivitas!$B$3:$B$563,$A9,Input_Konektivitas!$D$3:$D$563,">0"))=0,"",SUMIFS(Input_Konektivitas!$D$3:$D$563,Input_Konektivitas!$A$3:$A$563,$A9,Input_Konektivitas!$B$3:$B$563,N$3)+SUMIFS(Input_Konektivitas!$D$3:$D$563,Input_Konektivitas!$A$3:$A$563,N$3,Input_Konektivitas!$B$3:$B$563,$A9)) -> 3 | O9: =IF((COUNTIFS(Input_Konektivitas!$A$3:$A$563,$A9,Input_Konektivitas!$B$3:$B$563,O$3,Input_Konektivitas!$D$3:$D$563,">0")+COUNTIFS(Input_Konektivitas!$A$3:$A$563,O$3,Input_Konektivitas!$B$3:$B$563,$A9,Input_Konektivitas!$D$3:$D$563,">0"))=0,"",SUMIFS(Input_Konektivitas!$D$3:$D$563,Input_Konektivitas!$A$3:$A$563,$A9,Input_Konektivitas!$B$3:$B$563,O$3)+SUMIFS(Input_Konektivitas!$D$3:$D$563,Input_Konektivitas!$A$3:$A$563,O$3,Input_Konektivitas!$B$3:$B$563,$A9)) -> 1.58 | ... AI9: =IF((COUNTIFS(Input_Konektivitas!$A$3:$A$563,$A9,Input_Konektivitas!$B$3:$B$563,AI$3,Input_Konektivitas!$D$3:$D$563,">0")+COUNTIFS(Input_Konektivitas!$A$3:$A$563,AI$3,Input_Konektivitas!$B$3:$B$563,$A9,Input_Konektivitas!$D$3:$D$563,">0"))=0,"",SUMIFS(Input_Konektivitas!$D$3:$D$563,Input_Konektivitas!$A$3:$A$563,$A9,Input_Konektivitas!$B$3:$B$563,AI$3)+SUMIFS(Input_Konektivitas!$D$3:$D$563,Input_Konektivitas!$A$3:$A$563,AI$3,Input_Konektivitas!$B$3:$B$563,$A9)) -> 10.17
A10: Bengkulu | B10: =IF((COUNTIFS(Input_Konektivitas!$A$3:$A$563,$A10,Input_Konektivitas!$B$3:$B$563,B$3,Input_Konektivitas!$D$3:$D$563,">0")+COUNTIFS(Input_Konektivitas!$A$3:$A$563,B$3,Input_Konektivitas!$B$3:$B$563,$A10,Input_Konektivitas!$D$3:$D$563,">0"))=0,"",SUMIFS(Input_Konektivitas!$D$3:$D$563,Input_Konektivitas!$A$3:$A$563,$A10,Input_Konektivitas!$B$3:$B$563,B$3)+SUMIFS(Input_Konektivitas!$D$3:$D$563,Input_Konektivitas!$A$3:$A$563,B$3,Input_Konektivitas!$B$3:$B$563,$A10)) -> 6.92 | C10: =IF((COUNTIFS(Input_Konektivitas!$A$3:$A$563,$A10,Input_Konektivitas!$B$3:$B$563,C$3,Input_Konektivitas!$D$3:$D$563,">0")+COUNTIFS(Input_Konektivitas!$A$3:$A$563,C$3,Input_Konektivitas!$B$3:$B$563,$A10,Input_Konektivitas!$D$3:$D$563,">0"))=0,"",SUMIFS(Input_Konektivitas!$D$3:$D$563,Input_Konektivitas!$A$3:$A$563,$A10,Input_Konektivitas!$B$3:$B$563,C$3)+SUMIFS(Input_Konektivitas!$D$3:$D$563,Input_Konektivitas!$A$3:$A$563,C$3,Input_Konektivitas!$B$3:$B$563,$A10)) -> 5.1667 | D10: =IF((COUNTIFS(Input_Konektivitas!$A$3:$A$563,$A10,Input_Konektivitas!$B$3:$B$563,D$3,Input_Konektivitas!$D$3:$D$563,">0")+COUNTIFS(Input_Konektivitas!$A$3:$A$563,D$3,Input_Konektivitas!$B$3:$B$563,$A10,Input_Konektivitas!$D$3:$D$563,">0"))=0,"",SUMIFS(Input_Konektivitas!$D$3:$D$563,Input_Konektivitas!$A$3:$A$563,$A10,Input_Konektivitas!$B$3:$B$563,D$3)+SUMIFS(Input_Konektivitas!$D$3:$D$563,Input_Konektivitas!$A$3:$A$563,D$3,Input_Konektivitas!$B$3:$B$563,$A10)) -> 5.33 | E10: =IF((COUNTIFS(Input_Konektivitas!$A$3:$A$563,$A10,Input_Konektivitas!$B$3:$B$563,E$3,Input_Konektivitas!$D$3:$D$563,">0")+COUNTIFS(Input_Konektivitas!$A$3:$A$563,E$3,Input_Konektivitas!$B$3:$B$563,$A10,Input_Konektivitas!$D$3:$D$563,">0"))=0,"",SUMIFS(Input_Konektivitas!$D$3:$D$563,Input_Konektivitas!$A$3:$A$563,$A10,Input_Konektivitas!$B$3:$B$563,E$3)+SUMIFS(Input_Konektivitas!$D$3:$D$563,Input_Konektivitas!$A$3:$A$563,E$3,Input_Konektivitas!$B$3:$B$563,$A10)) -> 4.83 | F10: =IF((COUNTIFS(Input_Konektivitas!$A$3:$A$563,$A10,Input_Konektivitas!$B$3:$B$563,F$3,Input_Konektivitas!$D$3:$D$563,">0")+COUNTIFS(Input_Konektivitas!$A$3:$A$563,F$3,Input_Konektivitas!$B$3:$B$563,$A10,Input_Konektivitas!$D$3:$D$563,">0"))=0,"",SUMIFS(Input_Konektivitas!$D$3:$D$563,Input_Konektivitas!$A$3:$A$563,$A10,Input_Konektivitas!$B$3:$B$563,F$3)+SUMIFS(Input_Konektivitas!$D$3:$D$563,Input_Konektivitas!$A$3:$A$563,F$3,Input_Konektivitas!$B$3:$B$563,$A10)) -> 5 | G10: =IF((COUNTIFS(Input_Konektivitas!$A$3:$A$563,$A10,Input_Konektivitas!$B$3:$B$563,G$3,Input_Konektivitas!$D$3:$D$563,">0")+COUNTIFS(Input_Konektivitas!$A$3:$A$563,G$3,Input_Konektivitas!$B$3:$B$563,$A10,Input_Konektivitas!$D$3:$D$563,">0"))=0,"",SUMIFS(Input_Konektivitas!$D$3:$D$563,Input_Konektivitas!$A$3:$A$563,$A10,Input_Konektivitas!$B$3:$B$563,G$3)+SUMIFS(Input_Konektivitas!$D$3:$D$563,Input_Konektivitas!$A$3:$A$563,G$3,Input_Konektivitas!$B$3:$B$563,$A10)) -> 4 | H10: 0 | I10: =IF((COUNTIFS(Input_Konektivitas!$A$3:$A$563,$A10,Input_Konektivitas!$B$3:$B$563,I$3,Input_Konektivitas!$D$3:$D$563,">0")+COUNTIFS(Input_Konektivitas!$A$3:$A$563,I$3,Input_Konektivitas!$B$3:$B$563,$A10,Input_Konektivitas!$D$3:$D$563,">0"))=0,"",SUMIFS(Input_Konektivitas!$D$3:$D$563,Input_Konektivitas!$A$3:$A$563,$A10,Input_Konektivitas!$B$3:$B$563,I$3)+SUMIFS(Input_Konektivitas!$D$3:$D$563,Input_Konektivitas!$A$3:$A$563,I$3,Input_Konektivitas!$B$3:$B$563,$A10)) -> 3.83 | J10: =IF((COUNTIFS(Input_Konektivitas!$A$3:$A$563,$A10,Input_Konektivitas!$B$3:$B$563,J$3,Input_Konektivitas!$D$3:$D$563,">0")+COUNTIFS(Input_Konektivitas!$A$3:$A$563,J$3,Input_Konektivitas!$B$3:$B$563,$A10,Input_Konektivitas!$D$3:$D$563,">0"))=0,"",SUMIFS(Input_Konektivitas!$D$3:$D$563,Input_Konektivitas!$A$3:$A$563,$A10,Input_Konektivitas!$B$3:$B$563,J$3)+SUMIFS(Input_Konektivitas!$D$3:$D$563,Input_Konektivitas!$A$3:$A$563,J$3,Input_Konektivitas!$B$3:$B$563,$A10)) -> 4.5 | K10: =IF((COUNTIFS(Input_Konektivitas!$A$3:$A$563,$A10,Input_Konektivitas!$B$3:$B$563,K$3,Input_Konektivitas!$D$3:$D$563,">0")+COUNTIFS(Input_Konektivitas!$A$3:$A$563,K$3,Input_Konektivitas!$B$3:$B$563,$A10,Input_Konektivitas!$D$3:$D$563,">0"))=0,"",SUMIFS(Input_Konektivitas!$D$3:$D$563,Input_Konektivitas!$A$3:$A$563,$A10,Input_Konektivitas!$B$3:$B$563,K$3)+SUMIFS(Input_Konektivitas!$D$3:$D$563,Input_Konektivitas!$A$3:$A$563,K$3,Input_Konektivitas!$B$3:$B$563,$A10)) -> 5.08 | L10: =IF((COUNTIFS(Input_Konektivitas!$A$3:$A$563,$A10,Input_Konektivitas!$B$3:$B$563,L$3,Input_Konektivitas!$D$3:$D$563,">0")+COUNTIFS(Input_Konektivitas!$A$3:$A$563,L$3,Input_Konektivitas!$B$3:$B$563,$A10,Input_Konektivitas!$D$3:$D$563,">0"))=0,"",SUMIFS(Input_Konektivitas!$D$3:$D$563,Input_Konektivitas!$A$3:$A$563,$A10,Input_Konektivitas!$B$3:$B$563,L$3)+SUMIFS(Input_Konektivitas!$D$3:$D$563,Input_Konektivitas!$A$3:$A$563,L$3,Input_Konektivitas!$B$3:$B$563,$A10)) -> 1.33 | M10: =IF((COUNTIFS(Input_Konektivitas!$A$3:$A$563,$A10,Input_Konektivitas!$B$3:$B$563,M$3,Input_Konektivitas!$D$3:$D$563,">0")+COUNTIFS(Input_Konektivitas!$A$3:$A$563,M$3,Input_Konektivitas!$B$3:$B$563,$A10,Input_Konektivitas!$D$3:$D$563,">0"))=0,"",SUMIFS(Input_Konektivitas!$D$3:$D$563,Input_Konektivitas!$A$3:$A$563,$A10,Input_Konektivitas!$B$3:$B$563,M$3)+SUMIFS(Input_Konektivitas!$D$3:$D$563,Input_Konektivitas!$A$3:$A$563,M$3,Input_Konektivitas!$B$3:$B$563,$A10)) | N10: =IF((COUNTIFS(Input_Konektivitas!$A$3:$A$563,$A10,Input_Konektivitas!$B$3:$B$563,N$3,Input_Konektivitas!$D$3:$D$563,">0")+COUNTIFS(Input_Konektivitas!$A$3:$A$563,N$3,Input_Konektivitas!$B$3:$B$563,$A10,Input_Konektivitas!$D$3:$D$563,">0"))=0,"",SUMIFS(Input_Konektivitas!$D$3:$D$563,Input_Konektivitas!$A$3:$A$563,$A10,Input_Konektivitas!$B$3:$B$563,N$3)+SUMIFS(Input_Konektivitas!$D$3:$D$563,Input_Konektivitas!$A$3:$A$563,N$3,Input_Konektivitas!$B$3:$B$563,$A10)) -> 3.33 | O10: =IF((COUNTIFS(Input_Konektivitas!$A$3:$A$563,$A10,Input_Konektivitas!$B$3:$B$563,O$3,Input_Konektivitas!$D$3:$D$563,">0")+COUNTIFS(Input_Konektivitas!$A$3:$A$563,O$3,Input_Konektivitas!$B$3:$B$563,$A10,Input_Konektivitas!$D$3:$D$563,">0"))=0,"",SUMIFS(Input_Konektivitas!$D$3:$D$563,Input_Konektivitas!$A$3:$A$563,$A10,Input_Konektivitas!$B$3:$B$563,O$3)+SUMIFS(Input_Konektivitas!$D$3:$D$563,Input_Konektivitas!$A$3:$A$563,O$3,Input_Konektivitas!$B$3:$B$563,$A10)) -> 3.67 | P10: =IF((COUNTIFS(Input_Konektivitas!$A$3:$A$563,$A10,Input_Konektivitas!$B$3:$B$563,P$3,Input_Konektivitas!$D$3:$D$563,">0")+COUNTIFS(Input_Konektivitas!$A$3:$A$563,P$3,Input_Konektivitas!$B$3:$B$563,$A10,Input_Konektivitas!$D$3:$D$563,">0"))=0,"",SUMIFS(Input_Konektivitas!$D$3:$D$563,Input_Konektivitas!$A$3:$A$563,$A10,Input_Konektivitas!$B$3:$B$563,P$3)+SUMIFS(Input_Konektivitas!$D$3:$D$563,Input_Konektivitas!$A$3:$A$563,P$3,Input_Konektivitas!$B$3:$B$563,$A10)) -> 3.75 | ... AI10: =IF((COUNTIFS(Input_Konektivitas!$A$3:$A$563,$A10,Input_Konektivitas!$B$3:$B$563,AI$3,Input_Konektivitas!$D$3:$D$563,">0")+COUNTIFS(Input_Konektivitas!$A$3:$A$563,AI$3,Input_Konektivitas!$B$3:$B$563,$A10,Input_Konektivitas!$D$3:$D$563,">0"))=0,"",SUMIFS(Input_Konektivitas!$D$3:$D$563,Input_Konektivitas!$A$3:$A$563,$A10,Input_Konektivitas!$B$3:$B$563,AI$3)+SUMIFS(Input_Konektivitas!$D$3:$D$563,Input_Konektivitas!$A$3:$A$563,AI$3,Input_Konektivitas!$B$3:$B$563,$A10)) -> 12.25
A11: Lampung | B11: =IF((COUNTIFS(Input_Konektivitas!$A$3:$A$563,$A11,Input_Konektivitas!$B$3:$B$563,B$3,Input_Konektivitas!$D$3:$D$563,">0")+COUNTIFS(Input_Konektivitas!$A$3:$A$563,B$3,Input_Konektivitas!$B$3:$B$563,$A11,Input_Konektivitas!$D$3:$D$563,">0"))=0,"",SUMIFS(Input_Konektivitas!$D$3:$D$563,Input_Konektivitas!$A$3:$A$563,$A11,Input_Konektivitas!$B$3:$B$563,B$3)+SUMIFS(Input_Konektivitas!$D$3:$D$563,Input_Konektivitas!$A$3:$A$563,B$3,Input_Konektivitas!$B$3:$B$563,$A11)) -> 5.58 | C11: =IF((COUNTIFS(Input_Konektivitas!$A$3:$A$563,$A11,Input_Konektivitas!$B$3:$B$563,C$3,Input_Konektivitas!$D$3:$D$563,">0")+COUNTIFS(Input_Konektivitas!$A$3:$A$563,C$3,Input_Konektivitas!$B$3:$B$563,$A11,Input_Konektivitas!$D$3:$D$563,">0"))=0,"",SUMIFS(Input_Konektivitas!$D$3:$D$563,Input_Konektivitas!$A$3:$A$563,$A11,Input_Konektivitas!$B$3:$B$563,C$3)+SUMIFS(Input_Konektivitas!$D$3:$D$563,Input_Konektivitas!$A$3:$A$563,C$3,Input_Konektivitas!$B$3:$B$563,$A11)) -> 4.167 | D11: =IF((COUNTIFS(Input_Konektivitas!$A$3:$A$563,$A11,Input_Konektivitas!$B$3:$B$563,D$3,Input_Konektivitas!$D$3:$D$563,">0")+COUNTIFS(Input_Konektivitas!$A$3:$A$563,D$3,Input_Konektivitas!$B$3:$B$563,$A11,Input_Konektivitas!$D$3:$D$563,">0"))=0,"",SUMIFS(Input_Konektivitas!$D$3:$D$563,Input_Konektivitas!$A$3:$A$563,$A11,Input_Konektivitas!$B$3:$B$563,D$3)+SUMIFS(Input_Konektivitas!$D$3:$D$563,Input_Konektivitas!$A$3:$A$563,D$3,Input_Konektivitas!$B$3:$B$563,$A11)) -> 4.833 | E11: =IF((COUNTIFS(Input_Konektivitas!$A$3:$A$563,$A11,Input_Konektivitas!$B$3:$B$563,E$3,Input_Konektivitas!$D$3:$D$563,">0")+COUNTIFS(Input_Konektivitas!$A$3:$A$563,E$3,Input_Konektivitas!$B$3:$B$563,$A11,Input_Konektivitas!$D$3:$D$563,">0"))=0,"",SUMIFS(Input_Konektivitas!$D$3:$D$563,Input_Konektivitas!$A$3:$A$563,$A11,Input_Konektivitas!$B$3:$B$563,E$3)+SUMIFS(Input_Konektivitas!$D$3:$D$563,Input_Konektivitas!$A$3:$A$563,E$3,Input_Konektivitas!$B$3:$B$563,$A11)) -> 3.75 | F11: =IF((COUNTIFS(Input_Konektivitas!$A$3:$A$563,$A11,Input_Konektivitas!$B$3:$B$563,F$3,Input_Konektivitas!$D$3:$D$563,">0")+COUNTIFS(Input_Konektivitas!$A$3:$A$563,F$3,Input_Konektivitas!$B$3:$B$563,$A11,Input_Konektivitas!$D$3:$D$563,">0"))=0,"",SUMIFS(Input_Konektivitas!$D$3:$D$563,Input_Konektivitas!$A$3:$A$563,$A11,Input_Konektivitas!$B$3:$B$563,F$3)+SUMIFS(Input_Konektivitas!$D$3:$D$563,Input_Konektivitas!$A$3:$A$563,F$3,Input_Konektivitas!$B$3:$B$563,$A11)) -> 3.75 | G11: =IF((COUNTIFS(Input_Konektivitas!$A$3:$A$563,$A11,Input_Konektivitas!$B$3:$B$563,G$3,Input_Konektivitas!$D$3:$D$563,">0")+COUNTIFS(Input_Konektivitas!$A$3:$A$563,G$3,Input_Konektivitas!$B$3:$B$563,$A11,Input_Konektivitas!$D$3:$D$563,">0"))=0,"",SUMIFS(Input_Konektivitas!$D$3:$D$563,Input_Konektivitas!$A$3:$A$563,$A11,Input_Konektivitas!$B$3:$B$563,G$3)+SUMIFS(Input_Konektivitas!$D$3:$D$563,Input_Konektivitas!$A$3:$A$563,G$3,Input_Konektivitas!$B$3:$B$563,$A11)) -> 2.92 | H11: =IF((COUNTIFS(Input_Konektivitas!$A$3:$A$563,$A11,Input_Konektivitas!$B$3:$B$563,H$3,Input_Konektivitas!$D$3:$D$563,">0")+COUNTIFS(Input_Konektivitas!$A$3:$A$563,H$3,Input_Konektivitas!$B$3:$B$563,$A11,Input_Konektivitas!$D$3:$D$563,">0"))=0,"",SUMIFS(Input_Konektivitas!$D$3:$D$563,Input_Konektivitas!$A$3:$A$563,$A11,Input_Konektivitas!$B$3:$B$563,H$3)+SUMIFS(Input_Konektivitas!$D$3:$D$563,Input_Konektivitas!$A$3:$A$563,H$3,Input_Konektivitas!$B$3:$B$563,$A11)) -> 3.83 | I11: 0 | J11: =IF((COUNTIFS(Input_Konektivitas!$A$3:$A$563,$A11,Input_Konektivitas!$B$3:$B$563,J$3,Input_Konektivitas!$D$3:$D$563,">0")+COUNTIFS(Input_Konektivitas!$A$3:$A$563,J$3,Input_Konektivitas!$B$3:$B$563,$A11,Input_Konektivitas!$D$3:$D$563,">0"))=0,"",SUMIFS(Input_Konektivitas!$D$3:$D$563,Input_Konektivitas!$A$3:$A$563,$A11,Input_Konektivitas!$B$3:$B$563,J$3)+SUMIFS(Input_Konektivitas!$D$3:$D$563,Input_Konektivitas!$A$3:$A$563,J$3,Input_Konektivitas!$B$3:$B$563,$A11)) -> 4.33 | K11: =IF((COUNTIFS(Input_Konektivitas!$A$3:$A$563,$A11,Input_Konektivitas!$B$3:$B$563,K$3,Input_Konektivitas!$D$3:$D$563,">0")+COUNTIFS(Input_Konektivitas!$A$3:$A$563,K$3,Input_Konektivitas!$B$3:$B$563,$A11,Input_Konektivitas!$D$3:$D$563,">0"))=0,"",SUMIFS(Input_Konektivitas!$D$3:$D$563,Input_Konektivitas!$A$3:$A$563,$A11,Input_Konektivitas!$B$3:$B$563,K$3)+SUMIFS(Input_Konektivitas!$D$3:$D$563,Input_Konektivitas!$A$3:$A$563,K$3,Input_Konektivitas!$B$3:$B$563,$A11)) -> 4 | L11: =IF((COUNTIFS(Input_Konektivitas!$A$3:$A$563,$A11,Input_Konektivitas!$B$3:$B$563,L$3,Input_Konektivitas!$D$3:$D$563,">0")+COUNTIFS(Input_Konektivitas!$A$3:$A$563,L$3,Input_Konektivitas!$B$3:$B$563,$A11,Input_Konektivitas!$D$3:$D$563,">0"))=0,"",SUMIFS(Input_Konektivitas!$D$3:$D$563,Input_Konektivitas!$A$3:$A$563,$A11,Input_Konektivitas!$B$3:$B$563,L$3)+SUMIFS(Input_Konektivitas!$D$3:$D$563,Input_Konektivitas!$A$3:$A$563,L$3,Input_Konektivitas!$B$3:$B$563,$A11)) -> 0.75 | M11: =IF((COUNTIFS(Input_Konektivitas!$A$3:$A$563,$A11,Input_Konektivitas!$B$3:$B$563,M$3,Input_Konektivitas!$D$3:$D$563,">0")+COUNTIFS(Input_Konektivitas!$A$3:$A$563,M$3,Input_Konektivitas!$B$3:$B$563,$A11,Input_Konektivitas!$D$3:$D$563,">0"))=0,"",SUMIFS(Input_Konektivitas!$D$3:$D$563,Input_Konektivitas!$A$3:$A$563,$A11,Input_Konektivitas!$B$3:$B$563,M$3)+SUMIFS(Input_Konektivitas!$D$3:$D$563,Input_Konektivitas!$A$3:$A$563,M$3,Input_Konektivitas!$B$3:$B$563,$A11)) -> 22.25 | N11: =IF((COUNTIFS(Input_Konektivitas!$A$3:$A$563,$A11,Input_Konektivitas!$B$3:$B$563,N$3,Input_Konektivitas!$D$3:$D$563,">0")+COUNTIFS(Input_Konektivitas!$A$3:$A$563,N$3,Input_Konektivitas!$B$3:$B$563,$A11,Input_Konektivitas!$D$3:$D$563,">0"))=0,"",SUMIFS(Input_Konektivitas!$D$3:$D$563,Input_Konektivitas!$A$3:$A$563,$A11,Input_Konektivitas!$B$3:$B$563,N$3)+SUMIFS(Input_Konektivitas!$D$3:$D$563,Input_Konektivitas!$A$3:$A$563,N$3,Input_Konektivitas!$B$3:$B$563,$A11)) -> 4.33 | O11: =IF((COUNTIFS(Input_Konektivitas!$A$3:$A$563,$A11,Input_Konektivitas!$B$3:$B$563,O$3,Input_Konektivitas!$D$3:$D$563,">0")+COUNTIFS(Input_Konektivitas!$A$3:$A$563,O$3,Input_Konektivitas!$B$3:$B$563,$A11,Input_Konektivitas!$D$3:$D$563,">0"))=0,"",SUMIFS(Input_Konektivitas!$D$3:$D$563,Input_Konektivitas!$A$3:$A$563,$A11,Input_Konektivitas!$B$3:$B$563,O$3)+SUMIFS(Input_Konektivitas!$D$3:$D$563,Input_Konektivitas!$A$3:$A$563,O$3,Input_Konektivitas!$B$3:$B$563,$A11)) -> 2.92 | P11: =IF((COUNTIFS(Input_Konektivitas!$A$3:$A$563,$A11,Input_Konektivitas!$B$3:$B$563,P$3,Input_Konektivitas!$D$3:$D$563,">0")+COUNTIFS(Input_Konektivitas!$A$3:$A$563,P$3,Input_Konektivitas!$B$3:$B$563,$A11,Input_Konektivitas!$D$3:$D$563,">0"))=0,"",SUMIFS(Input_Konektivitas!$D$3:$D$563,Input_Konektivitas!$A$3:$A$563,$A11,Input_Konektivitas!$B$3:$B$563,P$3)+SUMIFS(Input_Konektivitas!$D$3:$D$563,Input_Konektivitas!$A$3:$A$563,P$3,Input_Konektivitas!$B$3:$B$563,$A11)) -> 3.25 | Q11: =IF((COUNTIFS(Input_Konektivitas!$A$3:$A$563,$A11,Input_Konektivitas!$B$3:$B$563,Q$3,Input_Konektivitas!$D$3:$D$563,">0")+COUNTIFS(Input_Konektivitas!$A$3:$A$563,Q$3,Input_Konektivitas!$B$3:$B$563,$A11,Input_Konektivitas!$D$3:$D$563,">0"))=0,"",SUMIFS(Input_Konektivitas!$D$3:$D$563,Input_Konektivitas!$A$3:$A$563,$A11,Input_Konektivitas!$B$3:$B$563,Q$3)+SUMIFS(Input_Konektivitas!$D$3:$D$563,Input_Konektivitas!$A$3:$A$563,Q$3,Input_Konektivitas!$B$3:$B$563,$A11)) | ... AI11: =IF((COUNTIFS(Input_Konektivitas!$A$3:$A$563,$A11,Input_Konektivitas!$B$3:$B$563,AI$3,Input_Konektivitas!$D$3:$D$563,">0")+COUNTIFS(Input_Konektivitas!$A$3:$A$563,AI$3,Input_Konektivitas!$B$3:$B$563,$A11,Input_Konektivitas!$D$3:$D$563,">0"))=0,"",SUMIFS(Input_Konektivitas!$D$3:$D$563,Input_Konektivitas!$A$3:$A$563,$A11,Input_Konektivitas!$B$3:$B$563,AI$3)+SUMIFS(Input_Konektivitas!$D$3:$D$563,Input_Konektivitas!$A$3:$A$563,AI$3,Input_Konektivitas!$B$3:$B$563,$A11)) -> 11.25
